technique,model,Processing Time,Memory Usage,Accuracy
No Technique,Naive Bayes,0.06203103065490723,0.671875,1.0
No Technique,Naive Bayes,0.05424165725708008,0.6015625,1.0
No Technique,Naive Bayes,0.05408835411071777,0.67578125,1.0
No Technique,Naive Bayes,0.05753469467163086,0.609375,1.0
No Technique,Naive Bayes,0.05878090858459473,0.671875,1.0
No Technique,Naive Bayes,0.0676567554473877,0.66796875,1.0
No Technique,Naive Bayes,0.051872968673706055,0.67578125,1.0
No Technique,Naive Bayes,0.055350542068481445,0.67578125,1.0
No Technique,Naive Bayes,0.06384444236755371,0.671875,1.0
No Technique,Naive Bayes,0.05207347869873047,0.61328125,0.9666666666666667
No Technique,Naive Bayes,0.05353212356567383,0.67578125,1.0
No Technique,Naive Bayes,0.05865812301635742,0.671875,1.0
No Technique,Naive Bayes,0.06271052360534668,0.65234375,1.0
No Technique,Naive Bayes,0.05780839920043945,0.64453125,1.0
No Technique,Naive Bayes,0.07873702049255371,0.609375,1.0
No Technique,Naive Bayes,0.05344963073730469,0.671875,1.0
No Technique,Naive Bayes,0.10335803031921387,0.671875,1.0
No Technique,Naive Bayes,0.05365490913391113,0.5546875,0.9666666666666667
No Technique,Naive Bayes,0.07382082939147949,0.671875,0.9666666666666667
No Technique,Naive Bayes,0.057764291763305664,0.6484375,1.0
No Technique,SVM,0.09653949737548828,0.7109375,1.0
No Technique,SVM,0.11544632911682129,0.76953125,1.0
No Technique,SVM,0.14788460731506348,0.78515625,1.0
No Technique,SVM,0.13086557388305664,0.8359375,1.0
No Technique,SVM,0.12313675880432129,0.703125,1.0
No Technique,SVM,0.14489054679870605,0.78515625,1.0
No Technique,SVM,0.110626220703125,0.79296875,1.0
No Technique,SVM,0.1045527458190918,0.7734375,1.0
No Technique,SVM,0.10489916801452637,0.7890625,1.0
No Technique,SVM,0.10404610633850098,0.76953125,1.0
No Technique,SVM,0.11870956420898438,0.7734375,1.0
No Technique,SVM,0.13832807540893555,0.828125,1.0
No Technique,SVM,0.1294233798980713,0.77734375,1.0
No Technique,SVM,0.1828022003173828,0.7734375,1.0
No Technique,SVM,0.1862168312072754,0.83203125,1.0
No Technique,SVM,0.11204910278320312,0.70703125,1.0
No Technique,SVM,0.1531355381011963,0.76953125,1.0
No Technique,SVM,0.1104283332824707,0.86328125,1.0
No Technique,SVM,0.15127015113830566,0.7734375,1.0
No Technique,SVM,0.14267826080322266,0.8203125,1.0
Traceback (most recent call last):
  File "C:\Users\Estudo\Documents\Best-Classification-AI-testing\code\program_analysis.py", line 342, in <module>
    analysis = Analysis(given_dataset, given_technique, given_optimization, given_cross_validation, given_model)
               ^^^^^^^^^^^^^^^^^^^^^^^^^^^^^^^^^^^^^^^^^^^^^^^^^^^^^^^^^^^^^^^^^^^^^^^^^^^^^^^^^^^^^^^^^^^^^^^^^
  File "C:\Users\Estudo\Documents\Best-Classification-AI-testing\code\program_analysis.py", line 44, in __init__
    performed = PerformAnalysis(technique, model, optimization, prepared.X_train, \
                ^^^^^^^^^^^^^^^^^^^^^^^^^^^^^^^^^^^^^^^^^^^^^^^^^^^^^^^^^^^^^^^^^^^
  File "C:\Users\Estudo\Documents\Best-Classification-AI-testing\code\program_analysis.py", line 125, in __init__
    self.select_model(model, optimization)
  File "C:\Users\Estudo\Documents\Best-Classification-AI-testing\code\program_analysis.py", line 254, in select_model
    self.get_metrics(optimized_model)
  File "C:\Users\Estudo\Documents\Best-Classification-AI-testing\code\program_analysis.py", line 257, in get_metrics
    classifier.fit(self.X_train, self.y_train)
  File "C:\Users\Estudo\AppData\Local\Programs\Python\Python312\Lib\site-packages\sklearn\base.py", line 1473, in wrapper
    return fit_method(estimator, *args, **kwargs)
           ^^^^^^^^^^^^^^^^^^^^^^^^^^^^^^^^^^^^^^
  File "C:\Users\Estudo\AppData\Local\Programs\Python\Python312\Lib\site-packages\sklearn\model_selection\_search.py", line 1019, in fit
    self._run_search(evaluate_candidates)
  File "C:\Users\Estudo\AppData\Local\Programs\Python\Python312\Lib\site-packages\sklearn\model_selection\_search.py", line 1573, in _run_search
    evaluate_candidates(ParameterGrid(self.param_grid))
  File "C:\Users\Estudo\AppData\Local\Programs\Python\Python312\Lib\site-packages\sklearn\model_selection\_search.py", line 996, in evaluate_candidates
    _warn_or_raise_about_fit_failures(out, self.error_score)
  File "C:\Users\Estudo\AppData\Local\Programs\Python\Python312\Lib\site-packages\sklearn\model_selection\_validation.py", line 529, in _warn_or_raise_about_fit_failures
    raise ValueError(all_fits_failed_message)
ValueError: 
All the 45 fits failed.
It is very likely that your model is misconfigured.
You can try to debug the error by setting error_score='raise'.

Below are more details about the failures:
--------------------------------------------------------------------------------
15 fits failed with the following error:
Traceback (most recent call last):
  File "C:\Users\Estudo\AppData\Local\Programs\Python\Python312\Lib\site-packages\sklearn\model_selection\_validation.py", line 888, in _fit_and_score
    estimator.fit(X_train, y_train, **fit_params)
  File "C:\Users\Estudo\AppData\Local\Programs\Python\Python312\Lib\site-packages\sklearn\base.py", line 1466, in wrapper
    estimator._validate_params()
  File "C:\Users\Estudo\AppData\Local\Programs\Python\Python312\Lib\site-packages\sklearn\base.py", line 666, in _validate_params
    validate_parameter_constraints(
  File "C:\Users\Estudo\AppData\Local\Programs\Python\Python312\Lib\site-packages\sklearn\utils\_param_validation.py", line 95, in validate_parameter_constraints
    raise InvalidParameterError(
sklearn.utils._param_validation.InvalidParameterError: The 'learning_rate' parameter of MLPClassifier must be a str among {'adaptive', 'invscaling', 'constant'}. Got 300 instead.

--------------------------------------------------------------------------------
15 fits failed with the following error:
Traceback (most recent call last):
  File "C:\Users\Estudo\AppData\Local\Programs\Python\Python312\Lib\site-packages\sklearn\model_selection\_validation.py", line 888, in _fit_and_score
    estimator.fit(X_train, y_train, **fit_params)
  File "C:\Users\Estudo\AppData\Local\Programs\Python\Python312\Lib\site-packages\sklearn\base.py", line 1466, in wrapper
    estimator._validate_params()
  File "C:\Users\Estudo\AppData\Local\Programs\Python\Python312\Lib\site-packages\sklearn\base.py", line 666, in _validate_params
    validate_parameter_constraints(
  File "C:\Users\Estudo\AppData\Local\Programs\Python\Python312\Lib\site-packages\sklearn\utils\_param_validation.py", line 95, in validate_parameter_constraints
    raise InvalidParameterError(
sklearn.utils._param_validation.InvalidParameterError: The 'learning_rate' parameter of MLPClassifier must be a str among {'adaptive', 'invscaling', 'constant'}. Got 400 instead.

--------------------------------------------------------------------------------
15 fits failed with the following error:
Traceback (most recent call last):
  File "C:\Users\Estudo\AppData\Local\Programs\Python\Python312\Lib\site-packages\sklearn\model_selection\_validation.py", line 888, in _fit_and_score
    estimator.fit(X_train, y_train, **fit_params)
  File "C:\Users\Estudo\AppData\Local\Programs\Python\Python312\Lib\site-packages\sklearn\base.py", line 1466, in wrapper
    estimator._validate_params()
  File "C:\Users\Estudo\AppData\Local\Programs\Python\Python312\Lib\site-packages\sklearn\base.py", line 666, in _validate_params
    validate_parameter_constraints(
  File "C:\Users\Estudo\AppData\Local\Programs\Python\Python312\Lib\site-packages\sklearn\utils\_param_validation.py", line 95, in validate_parameter_constraints
    raise InvalidParameterError(
sklearn.utils._param_validation.InvalidParameterError: The 'learning_rate' parameter of MLPClassifier must be a str among {'adaptive', 'invscaling', 'constant'}. Got 500 instead.

Traceback (most recent call last):
  File "C:\Users\Estudo\Documents\Best-Classification-AI-testing\code\program_analysis.py", line 342, in <module>
    analysis = Analysis(given_dataset, given_technique, given_optimization, given_cross_validation, given_model)
               ^^^^^^^^^^^^^^^^^^^^^^^^^^^^^^^^^^^^^^^^^^^^^^^^^^^^^^^^^^^^^^^^^^^^^^^^^^^^^^^^^^^^^^^^^^^^^^^^^
  File "C:\Users\Estudo\Documents\Best-Classification-AI-testing\code\program_analysis.py", line 44, in __init__
    performed = PerformAnalysis(technique, model, optimization, prepared.X_train, \
                ^^^^^^^^^^^^^^^^^^^^^^^^^^^^^^^^^^^^^^^^^^^^^^^^^^^^^^^^^^^^^^^^^^^
  File "C:\Users\Estudo\Documents\Best-Classification-AI-testing\code\program_analysis.py", line 125, in __init__
    self.select_model(model, optimization)
  File "C:\Users\Estudo\Documents\Best-Classification-AI-testing\code\program_analysis.py", line 254, in select_model
    self.get_metrics(optimized_model)
  File "C:\Users\Estudo\Documents\Best-Classification-AI-testing\code\program_analysis.py", line 257, in get_metrics
    classifier.fit(self.X_train, self.y_train)
  File "C:\Users\Estudo\AppData\Local\Programs\Python\Python312\Lib\site-packages\sklearn\base.py", line 1473, in wrapper
    return fit_method(estimator, *args, **kwargs)
           ^^^^^^^^^^^^^^^^^^^^^^^^^^^^^^^^^^^^^^
  File "C:\Users\Estudo\AppData\Local\Programs\Python\Python312\Lib\site-packages\sklearn\model_selection\_search.py", line 1019, in fit
    self._run_search(evaluate_candidates)
  File "C:\Users\Estudo\AppData\Local\Programs\Python\Python312\Lib\site-packages\sklearn\model_selection\_search.py", line 1573, in _run_search
    evaluate_candidates(ParameterGrid(self.param_grid))
  File "C:\Users\Estudo\AppData\Local\Programs\Python\Python312\Lib\site-packages\sklearn\model_selection\_search.py", line 996, in evaluate_candidates
    _warn_or_raise_about_fit_failures(out, self.error_score)
  File "C:\Users\Estudo\AppData\Local\Programs\Python\Python312\Lib\site-packages\sklearn\model_selection\_validation.py", line 529, in _warn_or_raise_about_fit_failures
    raise ValueError(all_fits_failed_message)
ValueError: 
All the 45 fits failed.
It is very likely that your model is misconfigured.
You can try to debug the error by setting error_score='raise'.

Below are more details about the failures:
--------------------------------------------------------------------------------
15 fits failed with the following error:
Traceback (most recent call last):
  File "C:\Users\Estudo\AppData\Local\Programs\Python\Python312\Lib\site-packages\sklearn\model_selection\_validation.py", line 888, in _fit_and_score
    estimator.fit(X_train, y_train, **fit_params)
  File "C:\Users\Estudo\AppData\Local\Programs\Python\Python312\Lib\site-packages\sklearn\base.py", line 1466, in wrapper
    estimator._validate_params()
  File "C:\Users\Estudo\AppData\Local\Programs\Python\Python312\Lib\site-packages\sklearn\base.py", line 666, in _validate_params
    validate_parameter_constraints(
  File "C:\Users\Estudo\AppData\Local\Programs\Python\Python312\Lib\site-packages\sklearn\utils\_param_validation.py", line 95, in validate_parameter_constraints
    raise InvalidParameterError(
sklearn.utils._param_validation.InvalidParameterError: The 'learning_rate' parameter of MLPClassifier must be a str among {'constant', 'invscaling', 'adaptive'}. Got 300 instead.

--------------------------------------------------------------------------------
15 fits failed with the following error:
Traceback (most recent call last):
  File "C:\Users\Estudo\AppData\Local\Programs\Python\Python312\Lib\site-packages\sklearn\model_selection\_validation.py", line 888, in _fit_and_score
    estimator.fit(X_train, y_train, **fit_params)
  File "C:\Users\Estudo\AppData\Local\Programs\Python\Python312\Lib\site-packages\sklearn\base.py", line 1466, in wrapper
    estimator._validate_params()
  File "C:\Users\Estudo\AppData\Local\Programs\Python\Python312\Lib\site-packages\sklearn\base.py", line 666, in _validate_params
    validate_parameter_constraints(
  File "C:\Users\Estudo\AppData\Local\Programs\Python\Python312\Lib\site-packages\sklearn\utils\_param_validation.py", line 95, in validate_parameter_constraints
    raise InvalidParameterError(
sklearn.utils._param_validation.InvalidParameterError: The 'learning_rate' parameter of MLPClassifier must be a str among {'constant', 'invscaling', 'adaptive'}. Got 400 instead.

--------------------------------------------------------------------------------
15 fits failed with the following error:
Traceback (most recent call last):
  File "C:\Users\Estudo\AppData\Local\Programs\Python\Python312\Lib\site-packages\sklearn\model_selection\_validation.py", line 888, in _fit_and_score
    estimator.fit(X_train, y_train, **fit_params)
  File "C:\Users\Estudo\AppData\Local\Programs\Python\Python312\Lib\site-packages\sklearn\base.py", line 1466, in wrapper
    estimator._validate_params()
  File "C:\Users\Estudo\AppData\Local\Programs\Python\Python312\Lib\site-packages\sklearn\base.py", line 666, in _validate_params
    validate_parameter_constraints(
  File "C:\Users\Estudo\AppData\Local\Programs\Python\Python312\Lib\site-packages\sklearn\utils\_param_validation.py", line 95, in validate_parameter_constraints
    raise InvalidParameterError(
sklearn.utils._param_validation.InvalidParameterError: The 'learning_rate' parameter of MLPClassifier must be a str among {'constant', 'invscaling', 'adaptive'}. Got 500 instead.

Traceback (most recent call last):
  File "C:\Users\Estudo\Documents\Best-Classification-AI-testing\code\program_analysis.py", line 342, in <module>
    analysis = Analysis(given_dataset, given_technique, given_optimization, given_cross_validation, given_model)
               ^^^^^^^^^^^^^^^^^^^^^^^^^^^^^^^^^^^^^^^^^^^^^^^^^^^^^^^^^^^^^^^^^^^^^^^^^^^^^^^^^^^^^^^^^^^^^^^^^
  File "C:\Users\Estudo\Documents\Best-Classification-AI-testing\code\program_analysis.py", line 44, in __init__
    performed = PerformAnalysis(technique, model, optimization, prepared.X_train, \
                ^^^^^^^^^^^^^^^^^^^^^^^^^^^^^^^^^^^^^^^^^^^^^^^^^^^^^^^^^^^^^^^^^^^
  File "C:\Users\Estudo\Documents\Best-Classification-AI-testing\code\program_analysis.py", line 125, in __init__
    self.select_model(model, optimization)
  File "C:\Users\Estudo\Documents\Best-Classification-AI-testing\code\program_analysis.py", line 254, in select_model
    self.get_metrics(optimized_model)
  File "C:\Users\Estudo\Documents\Best-Classification-AI-testing\code\program_analysis.py", line 257, in get_metrics
    classifier.fit(self.X_train, self.y_train)
  File "C:\Users\Estudo\AppData\Local\Programs\Python\Python312\Lib\site-packages\sklearn\base.py", line 1473, in wrapper
    return fit_method(estimator, *args, **kwargs)
           ^^^^^^^^^^^^^^^^^^^^^^^^^^^^^^^^^^^^^^
  File "C:\Users\Estudo\AppData\Local\Programs\Python\Python312\Lib\site-packages\sklearn\model_selection\_search.py", line 1019, in fit
    self._run_search(evaluate_candidates)
  File "C:\Users\Estudo\AppData\Local\Programs\Python\Python312\Lib\site-packages\sklearn\model_selection\_search.py", line 1573, in _run_search
    evaluate_candidates(ParameterGrid(self.param_grid))
  File "C:\Users\Estudo\AppData\Local\Programs\Python\Python312\Lib\site-packages\sklearn\model_selection\_search.py", line 996, in evaluate_candidates
    _warn_or_raise_about_fit_failures(out, self.error_score)
  File "C:\Users\Estudo\AppData\Local\Programs\Python\Python312\Lib\site-packages\sklearn\model_selection\_validation.py", line 529, in _warn_or_raise_about_fit_failures
    raise ValueError(all_fits_failed_message)
ValueError: 
All the 45 fits failed.
It is very likely that your model is misconfigured.
You can try to debug the error by setting error_score='raise'.

Below are more details about the failures:
--------------------------------------------------------------------------------
15 fits failed with the following error:
Traceback (most recent call last):
  File "C:\Users\Estudo\AppData\Local\Programs\Python\Python312\Lib\site-packages\sklearn\model_selection\_validation.py", line 888, in _fit_and_score
    estimator.fit(X_train, y_train, **fit_params)
  File "C:\Users\Estudo\AppData\Local\Programs\Python\Python312\Lib\site-packages\sklearn\base.py", line 1466, in wrapper
    estimator._validate_params()
  File "C:\Users\Estudo\AppData\Local\Programs\Python\Python312\Lib\site-packages\sklearn\base.py", line 666, in _validate_params
    validate_parameter_constraints(
  File "C:\Users\Estudo\AppData\Local\Programs\Python\Python312\Lib\site-packages\sklearn\utils\_param_validation.py", line 95, in validate_parameter_constraints
    raise InvalidParameterError(
sklearn.utils._param_validation.InvalidParameterError: The 'learning_rate' parameter of MLPClassifier must be a str among {'invscaling', 'adaptive', 'constant'}. Got 300 instead.

--------------------------------------------------------------------------------
15 fits failed with the following error:
Traceback (most recent call last):
  File "C:\Users\Estudo\AppData\Local\Programs\Python\Python312\Lib\site-packages\sklearn\model_selection\_validation.py", line 888, in _fit_and_score
    estimator.fit(X_train, y_train, **fit_params)
  File "C:\Users\Estudo\AppData\Local\Programs\Python\Python312\Lib\site-packages\sklearn\base.py", line 1466, in wrapper
    estimator._validate_params()
  File "C:\Users\Estudo\AppData\Local\Programs\Python\Python312\Lib\site-packages\sklearn\base.py", line 666, in _validate_params
    validate_parameter_constraints(
  File "C:\Users\Estudo\AppData\Local\Programs\Python\Python312\Lib\site-packages\sklearn\utils\_param_validation.py", line 95, in validate_parameter_constraints
    raise InvalidParameterError(
sklearn.utils._param_validation.InvalidParameterError: The 'learning_rate' parameter of MLPClassifier must be a str among {'invscaling', 'adaptive', 'constant'}. Got 400 instead.

--------------------------------------------------------------------------------
15 fits failed with the following error:
Traceback (most recent call last):
  File "C:\Users\Estudo\AppData\Local\Programs\Python\Python312\Lib\site-packages\sklearn\model_selection\_validation.py", line 888, in _fit_and_score
    estimator.fit(X_train, y_train, **fit_params)
  File "C:\Users\Estudo\AppData\Local\Programs\Python\Python312\Lib\site-packages\sklearn\base.py", line 1466, in wrapper
    estimator._validate_params()
  File "C:\Users\Estudo\AppData\Local\Programs\Python\Python312\Lib\site-packages\sklearn\base.py", line 666, in _validate_params
    validate_parameter_constraints(
  File "C:\Users\Estudo\AppData\Local\Programs\Python\Python312\Lib\site-packages\sklearn\utils\_param_validation.py", line 95, in validate_parameter_constraints
    raise InvalidParameterError(
sklearn.utils._param_validation.InvalidParameterError: The 'learning_rate' parameter of MLPClassifier must be a str among {'invscaling', 'adaptive', 'constant'}. Got 500 instead.

Traceback (most recent call last):
  File "C:\Users\Estudo\Documents\Best-Classification-AI-testing\code\program_analysis.py", line 342, in <module>
    analysis = Analysis(given_dataset, given_technique, given_optimization, given_cross_validation, given_model)
               ^^^^^^^^^^^^^^^^^^^^^^^^^^^^^^^^^^^^^^^^^^^^^^^^^^^^^^^^^^^^^^^^^^^^^^^^^^^^^^^^^^^^^^^^^^^^^^^^^
  File "C:\Users\Estudo\Documents\Best-Classification-AI-testing\code\program_analysis.py", line 44, in __init__
    performed = PerformAnalysis(technique, model, optimization, prepared.X_train, \
                ^^^^^^^^^^^^^^^^^^^^^^^^^^^^^^^^^^^^^^^^^^^^^^^^^^^^^^^^^^^^^^^^^^^
  File "C:\Users\Estudo\Documents\Best-Classification-AI-testing\code\program_analysis.py", line 125, in __init__
    self.select_model(model, optimization)
  File "C:\Users\Estudo\Documents\Best-Classification-AI-testing\code\program_analysis.py", line 254, in select_model
    self.get_metrics(optimized_model)
  File "C:\Users\Estudo\Documents\Best-Classification-AI-testing\code\program_analysis.py", line 257, in get_metrics
    classifier.fit(self.X_train, self.y_train)
  File "C:\Users\Estudo\AppData\Local\Programs\Python\Python312\Lib\site-packages\sklearn\base.py", line 1473, in wrapper
    return fit_method(estimator, *args, **kwargs)
           ^^^^^^^^^^^^^^^^^^^^^^^^^^^^^^^^^^^^^^
  File "C:\Users\Estudo\AppData\Local\Programs\Python\Python312\Lib\site-packages\sklearn\model_selection\_search.py", line 1019, in fit
    self._run_search(evaluate_candidates)
  File "C:\Users\Estudo\AppData\Local\Programs\Python\Python312\Lib\site-packages\sklearn\model_selection\_search.py", line 1573, in _run_search
    evaluate_candidates(ParameterGrid(self.param_grid))
  File "C:\Users\Estudo\AppData\Local\Programs\Python\Python312\Lib\site-packages\sklearn\model_selection\_search.py", line 996, in evaluate_candidates
    _warn_or_raise_about_fit_failures(out, self.error_score)
  File "C:\Users\Estudo\AppData\Local\Programs\Python\Python312\Lib\site-packages\sklearn\model_selection\_validation.py", line 529, in _warn_or_raise_about_fit_failures
    raise ValueError(all_fits_failed_message)
ValueError: 
All the 45 fits failed.
It is very likely that your model is misconfigured.
You can try to debug the error by setting error_score='raise'.

Below are more details about the failures:
--------------------------------------------------------------------------------
15 fits failed with the following error:
Traceback (most recent call last):
  File "C:\Users\Estudo\AppData\Local\Programs\Python\Python312\Lib\site-packages\sklearn\model_selection\_validation.py", line 888, in _fit_and_score
    estimator.fit(X_train, y_train, **fit_params)
  File "C:\Users\Estudo\AppData\Local\Programs\Python\Python312\Lib\site-packages\sklearn\base.py", line 1466, in wrapper
    estimator._validate_params()
  File "C:\Users\Estudo\AppData\Local\Programs\Python\Python312\Lib\site-packages\sklearn\base.py", line 666, in _validate_params
    validate_parameter_constraints(
  File "C:\Users\Estudo\AppData\Local\Programs\Python\Python312\Lib\site-packages\sklearn\utils\_param_validation.py", line 95, in validate_parameter_constraints
    raise InvalidParameterError(
sklearn.utils._param_validation.InvalidParameterError: The 'learning_rate' parameter of MLPClassifier must be a str among {'invscaling', 'adaptive', 'constant'}. Got 300 instead.

--------------------------------------------------------------------------------
15 fits failed with the following error:
Traceback (most recent call last):
  File "C:\Users\Estudo\AppData\Local\Programs\Python\Python312\Lib\site-packages\sklearn\model_selection\_validation.py", line 888, in _fit_and_score
    estimator.fit(X_train, y_train, **fit_params)
  File "C:\Users\Estudo\AppData\Local\Programs\Python\Python312\Lib\site-packages\sklearn\base.py", line 1466, in wrapper
    estimator._validate_params()
  File "C:\Users\Estudo\AppData\Local\Programs\Python\Python312\Lib\site-packages\sklearn\base.py", line 666, in _validate_params
    validate_parameter_constraints(
  File "C:\Users\Estudo\AppData\Local\Programs\Python\Python312\Lib\site-packages\sklearn\utils\_param_validation.py", line 95, in validate_parameter_constraints
    raise InvalidParameterError(
sklearn.utils._param_validation.InvalidParameterError: The 'learning_rate' parameter of MLPClassifier must be a str among {'invscaling', 'adaptive', 'constant'}. Got 400 instead.

--------------------------------------------------------------------------------
15 fits failed with the following error:
Traceback (most recent call last):
  File "C:\Users\Estudo\AppData\Local\Programs\Python\Python312\Lib\site-packages\sklearn\model_selection\_validation.py", line 888, in _fit_and_score
    estimator.fit(X_train, y_train, **fit_params)
  File "C:\Users\Estudo\AppData\Local\Programs\Python\Python312\Lib\site-packages\sklearn\base.py", line 1466, in wrapper
    estimator._validate_params()
  File "C:\Users\Estudo\AppData\Local\Programs\Python\Python312\Lib\site-packages\sklearn\base.py", line 666, in _validate_params
    validate_parameter_constraints(
  File "C:\Users\Estudo\AppData\Local\Programs\Python\Python312\Lib\site-packages\sklearn\utils\_param_validation.py", line 95, in validate_parameter_constraints
    raise InvalidParameterError(
sklearn.utils._param_validation.InvalidParameterError: The 'learning_rate' parameter of MLPClassifier must be a str among {'invscaling', 'adaptive', 'constant'}. Got 500 instead.

Traceback (most recent call last):
  File "C:\Users\Estudo\Documents\Best-Classification-AI-testing\code\program_analysis.py", line 342, in <module>
    analysis = Analysis(given_dataset, given_technique, given_optimization, given_cross_validation, given_model)
               ^^^^^^^^^^^^^^^^^^^^^^^^^^^^^^^^^^^^^^^^^^^^^^^^^^^^^^^^^^^^^^^^^^^^^^^^^^^^^^^^^^^^^^^^^^^^^^^^^
  File "C:\Users\Estudo\Documents\Best-Classification-AI-testing\code\program_analysis.py", line 44, in __init__
    performed = PerformAnalysis(technique, model, optimization, prepared.X_train, \
                ^^^^^^^^^^^^^^^^^^^^^^^^^^^^^^^^^^^^^^^^^^^^^^^^^^^^^^^^^^^^^^^^^^^
  File "C:\Users\Estudo\Documents\Best-Classification-AI-testing\code\program_analysis.py", line 125, in __init__
    self.select_model(model, optimization)
  File "C:\Users\Estudo\Documents\Best-Classification-AI-testing\code\program_analysis.py", line 254, in select_model
    self.get_metrics(optimized_model)
  File "C:\Users\Estudo\Documents\Best-Classification-AI-testing\code\program_analysis.py", line 257, in get_metrics
    classifier.fit(self.X_train, self.y_train)
  File "C:\Users\Estudo\AppData\Local\Programs\Python\Python312\Lib\site-packages\sklearn\base.py", line 1473, in wrapper
    return fit_method(estimator, *args, **kwargs)
           ^^^^^^^^^^^^^^^^^^^^^^^^^^^^^^^^^^^^^^
  File "C:\Users\Estudo\AppData\Local\Programs\Python\Python312\Lib\site-packages\sklearn\model_selection\_search.py", line 1019, in fit
    self._run_search(evaluate_candidates)
  File "C:\Users\Estudo\AppData\Local\Programs\Python\Python312\Lib\site-packages\sklearn\model_selection\_search.py", line 1573, in _run_search
    evaluate_candidates(ParameterGrid(self.param_grid))
  File "C:\Users\Estudo\AppData\Local\Programs\Python\Python312\Lib\site-packages\sklearn\model_selection\_search.py", line 996, in evaluate_candidates
    _warn_or_raise_about_fit_failures(out, self.error_score)
  File "C:\Users\Estudo\AppData\Local\Programs\Python\Python312\Lib\site-packages\sklearn\model_selection\_validation.py", line 529, in _warn_or_raise_about_fit_failures
    raise ValueError(all_fits_failed_message)
ValueError: 
All the 45 fits failed.
It is very likely that your model is misconfigured.
You can try to debug the error by setting error_score='raise'.

Below are more details about the failures:
--------------------------------------------------------------------------------
15 fits failed with the following error:
Traceback (most recent call last):
  File "C:\Users\Estudo\AppData\Local\Programs\Python\Python312\Lib\site-packages\sklearn\model_selection\_validation.py", line 888, in _fit_and_score
    estimator.fit(X_train, y_train, **fit_params)
  File "C:\Users\Estudo\AppData\Local\Programs\Python\Python312\Lib\site-packages\sklearn\base.py", line 1466, in wrapper
    estimator._validate_params()
  File "C:\Users\Estudo\AppData\Local\Programs\Python\Python312\Lib\site-packages\sklearn\base.py", line 666, in _validate_params
    validate_parameter_constraints(
  File "C:\Users\Estudo\AppData\Local\Programs\Python\Python312\Lib\site-packages\sklearn\utils\_param_validation.py", line 95, in validate_parameter_constraints
    raise InvalidParameterError(
sklearn.utils._param_validation.InvalidParameterError: The 'learning_rate' parameter of MLPClassifier must be a str among {'constant', 'invscaling', 'adaptive'}. Got 300 instead.

--------------------------------------------------------------------------------
15 fits failed with the following error:
Traceback (most recent call last):
  File "C:\Users\Estudo\AppData\Local\Programs\Python\Python312\Lib\site-packages\sklearn\model_selection\_validation.py", line 888, in _fit_and_score
    estimator.fit(X_train, y_train, **fit_params)
  File "C:\Users\Estudo\AppData\Local\Programs\Python\Python312\Lib\site-packages\sklearn\base.py", line 1466, in wrapper
    estimator._validate_params()
  File "C:\Users\Estudo\AppData\Local\Programs\Python\Python312\Lib\site-packages\sklearn\base.py", line 666, in _validate_params
    validate_parameter_constraints(
  File "C:\Users\Estudo\AppData\Local\Programs\Python\Python312\Lib\site-packages\sklearn\utils\_param_validation.py", line 95, in validate_parameter_constraints
    raise InvalidParameterError(
sklearn.utils._param_validation.InvalidParameterError: The 'learning_rate' parameter of MLPClassifier must be a str among {'constant', 'invscaling', 'adaptive'}. Got 400 instead.

--------------------------------------------------------------------------------
15 fits failed with the following error:
Traceback (most recent call last):
  File "C:\Users\Estudo\AppData\Local\Programs\Python\Python312\Lib\site-packages\sklearn\model_selection\_validation.py", line 888, in _fit_and_score
    estimator.fit(X_train, y_train, **fit_params)
  File "C:\Users\Estudo\AppData\Local\Programs\Python\Python312\Lib\site-packages\sklearn\base.py", line 1466, in wrapper
    estimator._validate_params()
  File "C:\Users\Estudo\AppData\Local\Programs\Python\Python312\Lib\site-packages\sklearn\base.py", line 666, in _validate_params
    validate_parameter_constraints(
  File "C:\Users\Estudo\AppData\Local\Programs\Python\Python312\Lib\site-packages\sklearn\utils\_param_validation.py", line 95, in validate_parameter_constraints
    raise InvalidParameterError(
sklearn.utils._param_validation.InvalidParameterError: The 'learning_rate' parameter of MLPClassifier must be a str among {'constant', 'invscaling', 'adaptive'}. Got 500 instead.

Traceback (most recent call last):
  File "C:\Users\Estudo\Documents\Best-Classification-AI-testing\code\program_analysis.py", line 342, in <module>
    analysis = Analysis(given_dataset, given_technique, given_optimization, given_cross_validation, given_model)
               ^^^^^^^^^^^^^^^^^^^^^^^^^^^^^^^^^^^^^^^^^^^^^^^^^^^^^^^^^^^^^^^^^^^^^^^^^^^^^^^^^^^^^^^^^^^^^^^^^
  File "C:\Users\Estudo\Documents\Best-Classification-AI-testing\code\program_analysis.py", line 44, in __init__
    performed = PerformAnalysis(technique, model, optimization, prepared.X_train, \
                ^^^^^^^^^^^^^^^^^^^^^^^^^^^^^^^^^^^^^^^^^^^^^^^^^^^^^^^^^^^^^^^^^^^
  File "C:\Users\Estudo\Documents\Best-Classification-AI-testing\code\program_analysis.py", line 125, in __init__
    self.select_model(model, optimization)
  File "C:\Users\Estudo\Documents\Best-Classification-AI-testing\code\program_analysis.py", line 254, in select_model
    self.get_metrics(optimized_model)
  File "C:\Users\Estudo\Documents\Best-Classification-AI-testing\code\program_analysis.py", line 257, in get_metrics
    classifier.fit(self.X_train, self.y_train)
  File "C:\Users\Estudo\AppData\Local\Programs\Python\Python312\Lib\site-packages\sklearn\base.py", line 1473, in wrapper
    return fit_method(estimator, *args, **kwargs)
           ^^^^^^^^^^^^^^^^^^^^^^^^^^^^^^^^^^^^^^
  File "C:\Users\Estudo\AppData\Local\Programs\Python\Python312\Lib\site-packages\sklearn\model_selection\_search.py", line 1019, in fit
    self._run_search(evaluate_candidates)
  File "C:\Users\Estudo\AppData\Local\Programs\Python\Python312\Lib\site-packages\sklearn\model_selection\_search.py", line 1573, in _run_search
    evaluate_candidates(ParameterGrid(self.param_grid))
  File "C:\Users\Estudo\AppData\Local\Programs\Python\Python312\Lib\site-packages\sklearn\model_selection\_search.py", line 996, in evaluate_candidates
    _warn_or_raise_about_fit_failures(out, self.error_score)
  File "C:\Users\Estudo\AppData\Local\Programs\Python\Python312\Lib\site-packages\sklearn\model_selection\_validation.py", line 529, in _warn_or_raise_about_fit_failures
    raise ValueError(all_fits_failed_message)
ValueError: 
All the 45 fits failed.
It is very likely that your model is misconfigured.
You can try to debug the error by setting error_score='raise'.

Below are more details about the failures:
--------------------------------------------------------------------------------
15 fits failed with the following error:
Traceback (most recent call last):
  File "C:\Users\Estudo\AppData\Local\Programs\Python\Python312\Lib\site-packages\sklearn\model_selection\_validation.py", line 888, in _fit_and_score
    estimator.fit(X_train, y_train, **fit_params)
  File "C:\Users\Estudo\AppData\Local\Programs\Python\Python312\Lib\site-packages\sklearn\base.py", line 1466, in wrapper
    estimator._validate_params()
  File "C:\Users\Estudo\AppData\Local\Programs\Python\Python312\Lib\site-packages\sklearn\base.py", line 666, in _validate_params
    validate_parameter_constraints(
  File "C:\Users\Estudo\AppData\Local\Programs\Python\Python312\Lib\site-packages\sklearn\utils\_param_validation.py", line 95, in validate_parameter_constraints
    raise InvalidParameterError(
sklearn.utils._param_validation.InvalidParameterError: The 'learning_rate' parameter of MLPClassifier must be a str among {'invscaling', 'adaptive', 'constant'}. Got 300 instead.

--------------------------------------------------------------------------------
15 fits failed with the following error:
Traceback (most recent call last):
  File "C:\Users\Estudo\AppData\Local\Programs\Python\Python312\Lib\site-packages\sklearn\model_selection\_validation.py", line 888, in _fit_and_score
    estimator.fit(X_train, y_train, **fit_params)
  File "C:\Users\Estudo\AppData\Local\Programs\Python\Python312\Lib\site-packages\sklearn\base.py", line 1466, in wrapper
    estimator._validate_params()
  File "C:\Users\Estudo\AppData\Local\Programs\Python\Python312\Lib\site-packages\sklearn\base.py", line 666, in _validate_params
    validate_parameter_constraints(
  File "C:\Users\Estudo\AppData\Local\Programs\Python\Python312\Lib\site-packages\sklearn\utils\_param_validation.py", line 95, in validate_parameter_constraints
    raise InvalidParameterError(
sklearn.utils._param_validation.InvalidParameterError: The 'learning_rate' parameter of MLPClassifier must be a str among {'invscaling', 'adaptive', 'constant'}. Got 400 instead.

--------------------------------------------------------------------------------
15 fits failed with the following error:
Traceback (most recent call last):
  File "C:\Users\Estudo\AppData\Local\Programs\Python\Python312\Lib\site-packages\sklearn\model_selection\_validation.py", line 888, in _fit_and_score
    estimator.fit(X_train, y_train, **fit_params)
  File "C:\Users\Estudo\AppData\Local\Programs\Python\Python312\Lib\site-packages\sklearn\base.py", line 1466, in wrapper
    estimator._validate_params()
  File "C:\Users\Estudo\AppData\Local\Programs\Python\Python312\Lib\site-packages\sklearn\base.py", line 666, in _validate_params
    validate_parameter_constraints(
  File "C:\Users\Estudo\AppData\Local\Programs\Python\Python312\Lib\site-packages\sklearn\utils\_param_validation.py", line 95, in validate_parameter_constraints
    raise InvalidParameterError(
sklearn.utils._param_validation.InvalidParameterError: The 'learning_rate' parameter of MLPClassifier must be a str among {'invscaling', 'adaptive', 'constant'}. Got 500 instead.

Traceback (most recent call last):
  File "C:\Users\Estudo\Documents\Best-Classification-AI-testing\code\program_analysis.py", line 342, in <module>
    analysis = Analysis(given_dataset, given_technique, given_optimization, given_cross_validation, given_model)
               ^^^^^^^^^^^^^^^^^^^^^^^^^^^^^^^^^^^^^^^^^^^^^^^^^^^^^^^^^^^^^^^^^^^^^^^^^^^^^^^^^^^^^^^^^^^^^^^^^
  File "C:\Users\Estudo\Documents\Best-Classification-AI-testing\code\program_analysis.py", line 44, in __init__
    performed = PerformAnalysis(technique, model, optimization, prepared.X_train, \
                ^^^^^^^^^^^^^^^^^^^^^^^^^^^^^^^^^^^^^^^^^^^^^^^^^^^^^^^^^^^^^^^^^^^
  File "C:\Users\Estudo\Documents\Best-Classification-AI-testing\code\program_analysis.py", line 125, in __init__
    self.select_model(model, optimization)
  File "C:\Users\Estudo\Documents\Best-Classification-AI-testing\code\program_analysis.py", line 254, in select_model
    self.get_metrics(optimized_model)
  File "C:\Users\Estudo\Documents\Best-Classification-AI-testing\code\program_analysis.py", line 257, in get_metrics
    classifier.fit(self.X_train, self.y_train)
  File "C:\Users\Estudo\AppData\Local\Programs\Python\Python312\Lib\site-packages\sklearn\base.py", line 1473, in wrapper
    return fit_method(estimator, *args, **kwargs)
           ^^^^^^^^^^^^^^^^^^^^^^^^^^^^^^^^^^^^^^
  File "C:\Users\Estudo\AppData\Local\Programs\Python\Python312\Lib\site-packages\sklearn\model_selection\_search.py", line 1019, in fit
    self._run_search(evaluate_candidates)
  File "C:\Users\Estudo\AppData\Local\Programs\Python\Python312\Lib\site-packages\sklearn\model_selection\_search.py", line 1573, in _run_search
    evaluate_candidates(ParameterGrid(self.param_grid))
  File "C:\Users\Estudo\AppData\Local\Programs\Python\Python312\Lib\site-packages\sklearn\model_selection\_search.py", line 996, in evaluate_candidates
    _warn_or_raise_about_fit_failures(out, self.error_score)
  File "C:\Users\Estudo\AppData\Local\Programs\Python\Python312\Lib\site-packages\sklearn\model_selection\_validation.py", line 529, in _warn_or_raise_about_fit_failures
    raise ValueError(all_fits_failed_message)
ValueError: 
All the 45 fits failed.
It is very likely that your model is misconfigured.
You can try to debug the error by setting error_score='raise'.

Below are more details about the failures:
--------------------------------------------------------------------------------
15 fits failed with the following error:
Traceback (most recent call last):
  File "C:\Users\Estudo\AppData\Local\Programs\Python\Python312\Lib\site-packages\sklearn\model_selection\_validation.py", line 888, in _fit_and_score
    estimator.fit(X_train, y_train, **fit_params)
  File "C:\Users\Estudo\AppData\Local\Programs\Python\Python312\Lib\site-packages\sklearn\base.py", line 1466, in wrapper
    estimator._validate_params()
  File "C:\Users\Estudo\AppData\Local\Programs\Python\Python312\Lib\site-packages\sklearn\base.py", line 666, in _validate_params
    validate_parameter_constraints(
  File "C:\Users\Estudo\AppData\Local\Programs\Python\Python312\Lib\site-packages\sklearn\utils\_param_validation.py", line 95, in validate_parameter_constraints
    raise InvalidParameterError(
sklearn.utils._param_validation.InvalidParameterError: The 'learning_rate' parameter of MLPClassifier must be a str among {'constant', 'invscaling', 'adaptive'}. Got 300 instead.

--------------------------------------------------------------------------------
15 fits failed with the following error:
Traceback (most recent call last):
  File "C:\Users\Estudo\AppData\Local\Programs\Python\Python312\Lib\site-packages\sklearn\model_selection\_validation.py", line 888, in _fit_and_score
    estimator.fit(X_train, y_train, **fit_params)
  File "C:\Users\Estudo\AppData\Local\Programs\Python\Python312\Lib\site-packages\sklearn\base.py", line 1466, in wrapper
    estimator._validate_params()
  File "C:\Users\Estudo\AppData\Local\Programs\Python\Python312\Lib\site-packages\sklearn\base.py", line 666, in _validate_params
    validate_parameter_constraints(
  File "C:\Users\Estudo\AppData\Local\Programs\Python\Python312\Lib\site-packages\sklearn\utils\_param_validation.py", line 95, in validate_parameter_constraints
    raise InvalidParameterError(
sklearn.utils._param_validation.InvalidParameterError: The 'learning_rate' parameter of MLPClassifier must be a str among {'constant', 'invscaling', 'adaptive'}. Got 400 instead.

--------------------------------------------------------------------------------
15 fits failed with the following error:
Traceback (most recent call last):
  File "C:\Users\Estudo\AppData\Local\Programs\Python\Python312\Lib\site-packages\sklearn\model_selection\_validation.py", line 888, in _fit_and_score
    estimator.fit(X_train, y_train, **fit_params)
  File "C:\Users\Estudo\AppData\Local\Programs\Python\Python312\Lib\site-packages\sklearn\base.py", line 1466, in wrapper
    estimator._validate_params()
  File "C:\Users\Estudo\AppData\Local\Programs\Python\Python312\Lib\site-packages\sklearn\base.py", line 666, in _validate_params
    validate_parameter_constraints(
  File "C:\Users\Estudo\AppData\Local\Programs\Python\Python312\Lib\site-packages\sklearn\utils\_param_validation.py", line 95, in validate_parameter_constraints
    raise InvalidParameterError(
sklearn.utils._param_validation.InvalidParameterError: The 'learning_rate' parameter of MLPClassifier must be a str among {'constant', 'invscaling', 'adaptive'}. Got 500 instead.

Traceback (most recent call last):
  File "C:\Users\Estudo\Documents\Best-Classification-AI-testing\code\program_analysis.py", line 342, in <module>
    analysis = Analysis(given_dataset, given_technique, given_optimization, given_cross_validation, given_model)
               ^^^^^^^^^^^^^^^^^^^^^^^^^^^^^^^^^^^^^^^^^^^^^^^^^^^^^^^^^^^^^^^^^^^^^^^^^^^^^^^^^^^^^^^^^^^^^^^^^
  File "C:\Users\Estudo\Documents\Best-Classification-AI-testing\code\program_analysis.py", line 44, in __init__
    performed = PerformAnalysis(technique, model, optimization, prepared.X_train, \
                ^^^^^^^^^^^^^^^^^^^^^^^^^^^^^^^^^^^^^^^^^^^^^^^^^^^^^^^^^^^^^^^^^^^
  File "C:\Users\Estudo\Documents\Best-Classification-AI-testing\code\program_analysis.py", line 125, in __init__
    self.select_model(model, optimization)
  File "C:\Users\Estudo\Documents\Best-Classification-AI-testing\code\program_analysis.py", line 254, in select_model
    self.get_metrics(optimized_model)
  File "C:\Users\Estudo\Documents\Best-Classification-AI-testing\code\program_analysis.py", line 257, in get_metrics
    classifier.fit(self.X_train, self.y_train)
  File "C:\Users\Estudo\AppData\Local\Programs\Python\Python312\Lib\site-packages\sklearn\base.py", line 1473, in wrapper
    return fit_method(estimator, *args, **kwargs)
           ^^^^^^^^^^^^^^^^^^^^^^^^^^^^^^^^^^^^^^
  File "C:\Users\Estudo\AppData\Local\Programs\Python\Python312\Lib\site-packages\sklearn\model_selection\_search.py", line 1019, in fit
    self._run_search(evaluate_candidates)
  File "C:\Users\Estudo\AppData\Local\Programs\Python\Python312\Lib\site-packages\sklearn\model_selection\_search.py", line 1573, in _run_search
    evaluate_candidates(ParameterGrid(self.param_grid))
  File "C:\Users\Estudo\AppData\Local\Programs\Python\Python312\Lib\site-packages\sklearn\model_selection\_search.py", line 996, in evaluate_candidates
    _warn_or_raise_about_fit_failures(out, self.error_score)
  File "C:\Users\Estudo\AppData\Local\Programs\Python\Python312\Lib\site-packages\sklearn\model_selection\_validation.py", line 529, in _warn_or_raise_about_fit_failures
    raise ValueError(all_fits_failed_message)
ValueError: 
All the 45 fits failed.
It is very likely that your model is misconfigured.
You can try to debug the error by setting error_score='raise'.

Below are more details about the failures:
--------------------------------------------------------------------------------
15 fits failed with the following error:
Traceback (most recent call last):
  File "C:\Users\Estudo\AppData\Local\Programs\Python\Python312\Lib\site-packages\sklearn\model_selection\_validation.py", line 888, in _fit_and_score
    estimator.fit(X_train, y_train, **fit_params)
  File "C:\Users\Estudo\AppData\Local\Programs\Python\Python312\Lib\site-packages\sklearn\base.py", line 1466, in wrapper
    estimator._validate_params()
  File "C:\Users\Estudo\AppData\Local\Programs\Python\Python312\Lib\site-packages\sklearn\base.py", line 666, in _validate_params
    validate_parameter_constraints(
  File "C:\Users\Estudo\AppData\Local\Programs\Python\Python312\Lib\site-packages\sklearn\utils\_param_validation.py", line 95, in validate_parameter_constraints
    raise InvalidParameterError(
sklearn.utils._param_validation.InvalidParameterError: The 'learning_rate' parameter of MLPClassifier must be a str among {'invscaling', 'constant', 'adaptive'}. Got 300 instead.

--------------------------------------------------------------------------------
15 fits failed with the following error:
Traceback (most recent call last):
  File "C:\Users\Estudo\AppData\Local\Programs\Python\Python312\Lib\site-packages\sklearn\model_selection\_validation.py", line 888, in _fit_and_score
    estimator.fit(X_train, y_train, **fit_params)
  File "C:\Users\Estudo\AppData\Local\Programs\Python\Python312\Lib\site-packages\sklearn\base.py", line 1466, in wrapper
    estimator._validate_params()
  File "C:\Users\Estudo\AppData\Local\Programs\Python\Python312\Lib\site-packages\sklearn\base.py", line 666, in _validate_params
    validate_parameter_constraints(
  File "C:\Users\Estudo\AppData\Local\Programs\Python\Python312\Lib\site-packages\sklearn\utils\_param_validation.py", line 95, in validate_parameter_constraints
    raise InvalidParameterError(
sklearn.utils._param_validation.InvalidParameterError: The 'learning_rate' parameter of MLPClassifier must be a str among {'invscaling', 'constant', 'adaptive'}. Got 400 instead.

--------------------------------------------------------------------------------
15 fits failed with the following error:
Traceback (most recent call last):
  File "C:\Users\Estudo\AppData\Local\Programs\Python\Python312\Lib\site-packages\sklearn\model_selection\_validation.py", line 888, in _fit_and_score
    estimator.fit(X_train, y_train, **fit_params)
  File "C:\Users\Estudo\AppData\Local\Programs\Python\Python312\Lib\site-packages\sklearn\base.py", line 1466, in wrapper
    estimator._validate_params()
  File "C:\Users\Estudo\AppData\Local\Programs\Python\Python312\Lib\site-packages\sklearn\base.py", line 666, in _validate_params
    validate_parameter_constraints(
  File "C:\Users\Estudo\AppData\Local\Programs\Python\Python312\Lib\site-packages\sklearn\utils\_param_validation.py", line 95, in validate_parameter_constraints
    raise InvalidParameterError(
sklearn.utils._param_validation.InvalidParameterError: The 'learning_rate' parameter of MLPClassifier must be a str among {'invscaling', 'constant', 'adaptive'}. Got 500 instead.

Traceback (most recent call last):
  File "C:\Users\Estudo\Documents\Best-Classification-AI-testing\code\program_analysis.py", line 342, in <module>
    analysis = Analysis(given_dataset, given_technique, given_optimization, given_cross_validation, given_model)
               ^^^^^^^^^^^^^^^^^^^^^^^^^^^^^^^^^^^^^^^^^^^^^^^^^^^^^^^^^^^^^^^^^^^^^^^^^^^^^^^^^^^^^^^^^^^^^^^^^
  File "C:\Users\Estudo\Documents\Best-Classification-AI-testing\code\program_analysis.py", line 44, in __init__
    performed = PerformAnalysis(technique, model, optimization, prepared.X_train, \
                ^^^^^^^^^^^^^^^^^^^^^^^^^^^^^^^^^^^^^^^^^^^^^^^^^^^^^^^^^^^^^^^^^^^
  File "C:\Users\Estudo\Documents\Best-Classification-AI-testing\code\program_analysis.py", line 125, in __init__
    self.select_model(model, optimization)
  File "C:\Users\Estudo\Documents\Best-Classification-AI-testing\code\program_analysis.py", line 254, in select_model
    self.get_metrics(optimized_model)
  File "C:\Users\Estudo\Documents\Best-Classification-AI-testing\code\program_analysis.py", line 257, in get_metrics
    classifier.fit(self.X_train, self.y_train)
  File "C:\Users\Estudo\AppData\Local\Programs\Python\Python312\Lib\site-packages\sklearn\base.py", line 1473, in wrapper
    return fit_method(estimator, *args, **kwargs)
           ^^^^^^^^^^^^^^^^^^^^^^^^^^^^^^^^^^^^^^
  File "C:\Users\Estudo\AppData\Local\Programs\Python\Python312\Lib\site-packages\sklearn\model_selection\_search.py", line 1019, in fit
    self._run_search(evaluate_candidates)
  File "C:\Users\Estudo\AppData\Local\Programs\Python\Python312\Lib\site-packages\sklearn\model_selection\_search.py", line 1573, in _run_search
    evaluate_candidates(ParameterGrid(self.param_grid))
  File "C:\Users\Estudo\AppData\Local\Programs\Python\Python312\Lib\site-packages\sklearn\model_selection\_search.py", line 996, in evaluate_candidates
    _warn_or_raise_about_fit_failures(out, self.error_score)
  File "C:\Users\Estudo\AppData\Local\Programs\Python\Python312\Lib\site-packages\sklearn\model_selection\_validation.py", line 529, in _warn_or_raise_about_fit_failures
    raise ValueError(all_fits_failed_message)
ValueError: 
All the 45 fits failed.
It is very likely that your model is misconfigured.
You can try to debug the error by setting error_score='raise'.

Below are more details about the failures:
--------------------------------------------------------------------------------
15 fits failed with the following error:
Traceback (most recent call last):
  File "C:\Users\Estudo\AppData\Local\Programs\Python\Python312\Lib\site-packages\sklearn\model_selection\_validation.py", line 888, in _fit_and_score
    estimator.fit(X_train, y_train, **fit_params)
  File "C:\Users\Estudo\AppData\Local\Programs\Python\Python312\Lib\site-packages\sklearn\base.py", line 1466, in wrapper
    estimator._validate_params()
  File "C:\Users\Estudo\AppData\Local\Programs\Python\Python312\Lib\site-packages\sklearn\base.py", line 666, in _validate_params
    validate_parameter_constraints(
  File "C:\Users\Estudo\AppData\Local\Programs\Python\Python312\Lib\site-packages\sklearn\utils\_param_validation.py", line 95, in validate_parameter_constraints
    raise InvalidParameterError(
sklearn.utils._param_validation.InvalidParameterError: The 'learning_rate' parameter of MLPClassifier must be a str among {'constant', 'adaptive', 'invscaling'}. Got 300 instead.

--------------------------------------------------------------------------------
15 fits failed with the following error:
Traceback (most recent call last):
  File "C:\Users\Estudo\AppData\Local\Programs\Python\Python312\Lib\site-packages\sklearn\model_selection\_validation.py", line 888, in _fit_and_score
    estimator.fit(X_train, y_train, **fit_params)
  File "C:\Users\Estudo\AppData\Local\Programs\Python\Python312\Lib\site-packages\sklearn\base.py", line 1466, in wrapper
    estimator._validate_params()
  File "C:\Users\Estudo\AppData\Local\Programs\Python\Python312\Lib\site-packages\sklearn\base.py", line 666, in _validate_params
    validate_parameter_constraints(
  File "C:\Users\Estudo\AppData\Local\Programs\Python\Python312\Lib\site-packages\sklearn\utils\_param_validation.py", line 95, in validate_parameter_constraints
    raise InvalidParameterError(
sklearn.utils._param_validation.InvalidParameterError: The 'learning_rate' parameter of MLPClassifier must be a str among {'constant', 'adaptive', 'invscaling'}. Got 400 instead.

--------------------------------------------------------------------------------
15 fits failed with the following error:
Traceback (most recent call last):
  File "C:\Users\Estudo\AppData\Local\Programs\Python\Python312\Lib\site-packages\sklearn\model_selection\_validation.py", line 888, in _fit_and_score
    estimator.fit(X_train, y_train, **fit_params)
  File "C:\Users\Estudo\AppData\Local\Programs\Python\Python312\Lib\site-packages\sklearn\base.py", line 1466, in wrapper
    estimator._validate_params()
  File "C:\Users\Estudo\AppData\Local\Programs\Python\Python312\Lib\site-packages\sklearn\base.py", line 666, in _validate_params
    validate_parameter_constraints(
  File "C:\Users\Estudo\AppData\Local\Programs\Python\Python312\Lib\site-packages\sklearn\utils\_param_validation.py", line 95, in validate_parameter_constraints
    raise InvalidParameterError(
sklearn.utils._param_validation.InvalidParameterError: The 'learning_rate' parameter of MLPClassifier must be a str among {'constant', 'adaptive', 'invscaling'}. Got 500 instead.

Traceback (most recent call last):
  File "C:\Users\Estudo\Documents\Best-Classification-AI-testing\code\program_analysis.py", line 342, in <module>
    analysis = Analysis(given_dataset, given_technique, given_optimization, given_cross_validation, given_model)
               ^^^^^^^^^^^^^^^^^^^^^^^^^^^^^^^^^^^^^^^^^^^^^^^^^^^^^^^^^^^^^^^^^^^^^^^^^^^^^^^^^^^^^^^^^^^^^^^^^
  File "C:\Users\Estudo\Documents\Best-Classification-AI-testing\code\program_analysis.py", line 44, in __init__
    performed = PerformAnalysis(technique, model, optimization, prepared.X_train, \
                ^^^^^^^^^^^^^^^^^^^^^^^^^^^^^^^^^^^^^^^^^^^^^^^^^^^^^^^^^^^^^^^^^^^
  File "C:\Users\Estudo\Documents\Best-Classification-AI-testing\code\program_analysis.py", line 125, in __init__
    self.select_model(model, optimization)
  File "C:\Users\Estudo\Documents\Best-Classification-AI-testing\code\program_analysis.py", line 254, in select_model
    self.get_metrics(optimized_model)
  File "C:\Users\Estudo\Documents\Best-Classification-AI-testing\code\program_analysis.py", line 257, in get_metrics
    classifier.fit(self.X_train, self.y_train)
  File "C:\Users\Estudo\AppData\Local\Programs\Python\Python312\Lib\site-packages\sklearn\base.py", line 1473, in wrapper
    return fit_method(estimator, *args, **kwargs)
           ^^^^^^^^^^^^^^^^^^^^^^^^^^^^^^^^^^^^^^
  File "C:\Users\Estudo\AppData\Local\Programs\Python\Python312\Lib\site-packages\sklearn\model_selection\_search.py", line 1019, in fit
    self._run_search(evaluate_candidates)
  File "C:\Users\Estudo\AppData\Local\Programs\Python\Python312\Lib\site-packages\sklearn\model_selection\_search.py", line 1573, in _run_search
    evaluate_candidates(ParameterGrid(self.param_grid))
  File "C:\Users\Estudo\AppData\Local\Programs\Python\Python312\Lib\site-packages\sklearn\model_selection\_search.py", line 996, in evaluate_candidates
    _warn_or_raise_about_fit_failures(out, self.error_score)
  File "C:\Users\Estudo\AppData\Local\Programs\Python\Python312\Lib\site-packages\sklearn\model_selection\_validation.py", line 529, in _warn_or_raise_about_fit_failures
    raise ValueError(all_fits_failed_message)
ValueError: 
All the 45 fits failed.
It is very likely that your model is misconfigured.
You can try to debug the error by setting error_score='raise'.

Below are more details about the failures:
--------------------------------------------------------------------------------
15 fits failed with the following error:
Traceback (most recent call last):
  File "C:\Users\Estudo\AppData\Local\Programs\Python\Python312\Lib\site-packages\sklearn\model_selection\_validation.py", line 888, in _fit_and_score
    estimator.fit(X_train, y_train, **fit_params)
  File "C:\Users\Estudo\AppData\Local\Programs\Python\Python312\Lib\site-packages\sklearn\base.py", line 1466, in wrapper
    estimator._validate_params()
  File "C:\Users\Estudo\AppData\Local\Programs\Python\Python312\Lib\site-packages\sklearn\base.py", line 666, in _validate_params
    validate_parameter_constraints(
  File "C:\Users\Estudo\AppData\Local\Programs\Python\Python312\Lib\site-packages\sklearn\utils\_param_validation.py", line 95, in validate_parameter_constraints
    raise InvalidParameterError(
sklearn.utils._param_validation.InvalidParameterError: The 'learning_rate' parameter of MLPClassifier must be a str among {'constant', 'adaptive', 'invscaling'}. Got 300 instead.

--------------------------------------------------------------------------------
15 fits failed with the following error:
Traceback (most recent call last):
  File "C:\Users\Estudo\AppData\Local\Programs\Python\Python312\Lib\site-packages\sklearn\model_selection\_validation.py", line 888, in _fit_and_score
    estimator.fit(X_train, y_train, **fit_params)
  File "C:\Users\Estudo\AppData\Local\Programs\Python\Python312\Lib\site-packages\sklearn\base.py", line 1466, in wrapper
    estimator._validate_params()
  File "C:\Users\Estudo\AppData\Local\Programs\Python\Python312\Lib\site-packages\sklearn\base.py", line 666, in _validate_params
    validate_parameter_constraints(
  File "C:\Users\Estudo\AppData\Local\Programs\Python\Python312\Lib\site-packages\sklearn\utils\_param_validation.py", line 95, in validate_parameter_constraints
    raise InvalidParameterError(
sklearn.utils._param_validation.InvalidParameterError: The 'learning_rate' parameter of MLPClassifier must be a str among {'constant', 'adaptive', 'invscaling'}. Got 400 instead.

--------------------------------------------------------------------------------
15 fits failed with the following error:
Traceback (most recent call last):
  File "C:\Users\Estudo\AppData\Local\Programs\Python\Python312\Lib\site-packages\sklearn\model_selection\_validation.py", line 888, in _fit_and_score
    estimator.fit(X_train, y_train, **fit_params)
  File "C:\Users\Estudo\AppData\Local\Programs\Python\Python312\Lib\site-packages\sklearn\base.py", line 1466, in wrapper
    estimator._validate_params()
  File "C:\Users\Estudo\AppData\Local\Programs\Python\Python312\Lib\site-packages\sklearn\base.py", line 666, in _validate_params
    validate_parameter_constraints(
  File "C:\Users\Estudo\AppData\Local\Programs\Python\Python312\Lib\site-packages\sklearn\utils\_param_validation.py", line 95, in validate_parameter_constraints
    raise InvalidParameterError(
sklearn.utils._param_validation.InvalidParameterError: The 'learning_rate' parameter of MLPClassifier must be a str among {'constant', 'adaptive', 'invscaling'}. Got 500 instead.

Traceback (most recent call last):
  File "C:\Users\Estudo\Documents\Best-Classification-AI-testing\code\program_analysis.py", line 342, in <module>
    analysis = Analysis(given_dataset, given_technique, given_optimization, given_cross_validation, given_model)
               ^^^^^^^^^^^^^^^^^^^^^^^^^^^^^^^^^^^^^^^^^^^^^^^^^^^^^^^^^^^^^^^^^^^^^^^^^^^^^^^^^^^^^^^^^^^^^^^^^
  File "C:\Users\Estudo\Documents\Best-Classification-AI-testing\code\program_analysis.py", line 44, in __init__
    performed = PerformAnalysis(technique, model, optimization, prepared.X_train, \
                ^^^^^^^^^^^^^^^^^^^^^^^^^^^^^^^^^^^^^^^^^^^^^^^^^^^^^^^^^^^^^^^^^^^
  File "C:\Users\Estudo\Documents\Best-Classification-AI-testing\code\program_analysis.py", line 125, in __init__
    self.select_model(model, optimization)
  File "C:\Users\Estudo\Documents\Best-Classification-AI-testing\code\program_analysis.py", line 254, in select_model
    self.get_metrics(optimized_model)
  File "C:\Users\Estudo\Documents\Best-Classification-AI-testing\code\program_analysis.py", line 257, in get_metrics
    classifier.fit(self.X_train, self.y_train)
  File "C:\Users\Estudo\AppData\Local\Programs\Python\Python312\Lib\site-packages\sklearn\base.py", line 1473, in wrapper
    return fit_method(estimator, *args, **kwargs)
           ^^^^^^^^^^^^^^^^^^^^^^^^^^^^^^^^^^^^^^
  File "C:\Users\Estudo\AppData\Local\Programs\Python\Python312\Lib\site-packages\sklearn\model_selection\_search.py", line 1019, in fit
    self._run_search(evaluate_candidates)
  File "C:\Users\Estudo\AppData\Local\Programs\Python\Python312\Lib\site-packages\sklearn\model_selection\_search.py", line 1573, in _run_search
    evaluate_candidates(ParameterGrid(self.param_grid))
  File "C:\Users\Estudo\AppData\Local\Programs\Python\Python312\Lib\site-packages\sklearn\model_selection\_search.py", line 996, in evaluate_candidates
    _warn_or_raise_about_fit_failures(out, self.error_score)
  File "C:\Users\Estudo\AppData\Local\Programs\Python\Python312\Lib\site-packages\sklearn\model_selection\_validation.py", line 529, in _warn_or_raise_about_fit_failures
    raise ValueError(all_fits_failed_message)
ValueError: 
All the 45 fits failed.
It is very likely that your model is misconfigured.
You can try to debug the error by setting error_score='raise'.

Below are more details about the failures:
--------------------------------------------------------------------------------
15 fits failed with the following error:
Traceback (most recent call last):
  File "C:\Users\Estudo\AppData\Local\Programs\Python\Python312\Lib\site-packages\sklearn\model_selection\_validation.py", line 888, in _fit_and_score
    estimator.fit(X_train, y_train, **fit_params)
  File "C:\Users\Estudo\AppData\Local\Programs\Python\Python312\Lib\site-packages\sklearn\base.py", line 1466, in wrapper
    estimator._validate_params()
  File "C:\Users\Estudo\AppData\Local\Programs\Python\Python312\Lib\site-packages\sklearn\base.py", line 666, in _validate_params
    validate_parameter_constraints(
  File "C:\Users\Estudo\AppData\Local\Programs\Python\Python312\Lib\site-packages\sklearn\utils\_param_validation.py", line 95, in validate_parameter_constraints
    raise InvalidParameterError(
sklearn.utils._param_validation.InvalidParameterError: The 'learning_rate' parameter of MLPClassifier must be a str among {'constant', 'adaptive', 'invscaling'}. Got 300 instead.

--------------------------------------------------------------------------------
15 fits failed with the following error:
Traceback (most recent call last):
  File "C:\Users\Estudo\AppData\Local\Programs\Python\Python312\Lib\site-packages\sklearn\model_selection\_validation.py", line 888, in _fit_and_score
    estimator.fit(X_train, y_train, **fit_params)
  File "C:\Users\Estudo\AppData\Local\Programs\Python\Python312\Lib\site-packages\sklearn\base.py", line 1466, in wrapper
    estimator._validate_params()
  File "C:\Users\Estudo\AppData\Local\Programs\Python\Python312\Lib\site-packages\sklearn\base.py", line 666, in _validate_params
    validate_parameter_constraints(
  File "C:\Users\Estudo\AppData\Local\Programs\Python\Python312\Lib\site-packages\sklearn\utils\_param_validation.py", line 95, in validate_parameter_constraints
    raise InvalidParameterError(
sklearn.utils._param_validation.InvalidParameterError: The 'learning_rate' parameter of MLPClassifier must be a str among {'constant', 'adaptive', 'invscaling'}. Got 400 instead.

--------------------------------------------------------------------------------
15 fits failed with the following error:
Traceback (most recent call last):
  File "C:\Users\Estudo\AppData\Local\Programs\Python\Python312\Lib\site-packages\sklearn\model_selection\_validation.py", line 888, in _fit_and_score
    estimator.fit(X_train, y_train, **fit_params)
  File "C:\Users\Estudo\AppData\Local\Programs\Python\Python312\Lib\site-packages\sklearn\base.py", line 1466, in wrapper
    estimator._validate_params()
  File "C:\Users\Estudo\AppData\Local\Programs\Python\Python312\Lib\site-packages\sklearn\base.py", line 666, in _validate_params
    validate_parameter_constraints(
  File "C:\Users\Estudo\AppData\Local\Programs\Python\Python312\Lib\site-packages\sklearn\utils\_param_validation.py", line 95, in validate_parameter_constraints
    raise InvalidParameterError(
sklearn.utils._param_validation.InvalidParameterError: The 'learning_rate' parameter of MLPClassifier must be a str among {'constant', 'adaptive', 'invscaling'}. Got 500 instead.

Traceback (most recent call last):
  File "C:\Users\Estudo\Documents\Best-Classification-AI-testing\code\program_analysis.py", line 342, in <module>
    analysis = Analysis(given_dataset, given_technique, given_optimization, given_cross_validation, given_model)
               ^^^^^^^^^^^^^^^^^^^^^^^^^^^^^^^^^^^^^^^^^^^^^^^^^^^^^^^^^^^^^^^^^^^^^^^^^^^^^^^^^^^^^^^^^^^^^^^^^
  File "C:\Users\Estudo\Documents\Best-Classification-AI-testing\code\program_analysis.py", line 44, in __init__
    performed = PerformAnalysis(technique, model, optimization, prepared.X_train, \
                ^^^^^^^^^^^^^^^^^^^^^^^^^^^^^^^^^^^^^^^^^^^^^^^^^^^^^^^^^^^^^^^^^^^
  File "C:\Users\Estudo\Documents\Best-Classification-AI-testing\code\program_analysis.py", line 125, in __init__
    self.select_model(model, optimization)
  File "C:\Users\Estudo\Documents\Best-Classification-AI-testing\code\program_analysis.py", line 254, in select_model
    self.get_metrics(optimized_model)
  File "C:\Users\Estudo\Documents\Best-Classification-AI-testing\code\program_analysis.py", line 257, in get_metrics
    classifier.fit(self.X_train, self.y_train)
  File "C:\Users\Estudo\AppData\Local\Programs\Python\Python312\Lib\site-packages\sklearn\base.py", line 1473, in wrapper
    return fit_method(estimator, *args, **kwargs)
           ^^^^^^^^^^^^^^^^^^^^^^^^^^^^^^^^^^^^^^
  File "C:\Users\Estudo\AppData\Local\Programs\Python\Python312\Lib\site-packages\sklearn\model_selection\_search.py", line 1019, in fit
    self._run_search(evaluate_candidates)
  File "C:\Users\Estudo\AppData\Local\Programs\Python\Python312\Lib\site-packages\sklearn\model_selection\_search.py", line 1573, in _run_search
    evaluate_candidates(ParameterGrid(self.param_grid))
  File "C:\Users\Estudo\AppData\Local\Programs\Python\Python312\Lib\site-packages\sklearn\model_selection\_search.py", line 996, in evaluate_candidates
    _warn_or_raise_about_fit_failures(out, self.error_score)
  File "C:\Users\Estudo\AppData\Local\Programs\Python\Python312\Lib\site-packages\sklearn\model_selection\_validation.py", line 529, in _warn_or_raise_about_fit_failures
    raise ValueError(all_fits_failed_message)
ValueError: 
All the 45 fits failed.
It is very likely that your model is misconfigured.
You can try to debug the error by setting error_score='raise'.

Below are more details about the failures:
--------------------------------------------------------------------------------
15 fits failed with the following error:
Traceback (most recent call last):
  File "C:\Users\Estudo\AppData\Local\Programs\Python\Python312\Lib\site-packages\sklearn\model_selection\_validation.py", line 888, in _fit_and_score
    estimator.fit(X_train, y_train, **fit_params)
  File "C:\Users\Estudo\AppData\Local\Programs\Python\Python312\Lib\site-packages\sklearn\base.py", line 1466, in wrapper
    estimator._validate_params()
  File "C:\Users\Estudo\AppData\Local\Programs\Python\Python312\Lib\site-packages\sklearn\base.py", line 666, in _validate_params
    validate_parameter_constraints(
  File "C:\Users\Estudo\AppData\Local\Programs\Python\Python312\Lib\site-packages\sklearn\utils\_param_validation.py", line 95, in validate_parameter_constraints
    raise InvalidParameterError(
sklearn.utils._param_validation.InvalidParameterError: The 'learning_rate' parameter of MLPClassifier must be a str among {'constant', 'invscaling', 'adaptive'}. Got 300 instead.

--------------------------------------------------------------------------------
15 fits failed with the following error:
Traceback (most recent call last):
  File "C:\Users\Estudo\AppData\Local\Programs\Python\Python312\Lib\site-packages\sklearn\model_selection\_validation.py", line 888, in _fit_and_score
    estimator.fit(X_train, y_train, **fit_params)
  File "C:\Users\Estudo\AppData\Local\Programs\Python\Python312\Lib\site-packages\sklearn\base.py", line 1466, in wrapper
    estimator._validate_params()
  File "C:\Users\Estudo\AppData\Local\Programs\Python\Python312\Lib\site-packages\sklearn\base.py", line 666, in _validate_params
    validate_parameter_constraints(
  File "C:\Users\Estudo\AppData\Local\Programs\Python\Python312\Lib\site-packages\sklearn\utils\_param_validation.py", line 95, in validate_parameter_constraints
    raise InvalidParameterError(
sklearn.utils._param_validation.InvalidParameterError: The 'learning_rate' parameter of MLPClassifier must be a str among {'constant', 'invscaling', 'adaptive'}. Got 400 instead.

--------------------------------------------------------------------------------
15 fits failed with the following error:
Traceback (most recent call last):
  File "C:\Users\Estudo\AppData\Local\Programs\Python\Python312\Lib\site-packages\sklearn\model_selection\_validation.py", line 888, in _fit_and_score
    estimator.fit(X_train, y_train, **fit_params)
  File "C:\Users\Estudo\AppData\Local\Programs\Python\Python312\Lib\site-packages\sklearn\base.py", line 1466, in wrapper
    estimator._validate_params()
  File "C:\Users\Estudo\AppData\Local\Programs\Python\Python312\Lib\site-packages\sklearn\base.py", line 666, in _validate_params
    validate_parameter_constraints(
  File "C:\Users\Estudo\AppData\Local\Programs\Python\Python312\Lib\site-packages\sklearn\utils\_param_validation.py", line 95, in validate_parameter_constraints
    raise InvalidParameterError(
sklearn.utils._param_validation.InvalidParameterError: The 'learning_rate' parameter of MLPClassifier must be a str among {'constant', 'invscaling', 'adaptive'}. Got 500 instead.

Traceback (most recent call last):
  File "C:\Users\Estudo\Documents\Best-Classification-AI-testing\code\program_analysis.py", line 342, in <module>
    analysis = Analysis(given_dataset, given_technique, given_optimization, given_cross_validation, given_model)
               ^^^^^^^^^^^^^^^^^^^^^^^^^^^^^^^^^^^^^^^^^^^^^^^^^^^^^^^^^^^^^^^^^^^^^^^^^^^^^^^^^^^^^^^^^^^^^^^^^
  File "C:\Users\Estudo\Documents\Best-Classification-AI-testing\code\program_analysis.py", line 44, in __init__
    performed = PerformAnalysis(technique, model, optimization, prepared.X_train, \
                ^^^^^^^^^^^^^^^^^^^^^^^^^^^^^^^^^^^^^^^^^^^^^^^^^^^^^^^^^^^^^^^^^^^
  File "C:\Users\Estudo\Documents\Best-Classification-AI-testing\code\program_analysis.py", line 125, in __init__
    self.select_model(model, optimization)
  File "C:\Users\Estudo\Documents\Best-Classification-AI-testing\code\program_analysis.py", line 254, in select_model
    self.get_metrics(optimized_model)
  File "C:\Users\Estudo\Documents\Best-Classification-AI-testing\code\program_analysis.py", line 257, in get_metrics
    classifier.fit(self.X_train, self.y_train)
  File "C:\Users\Estudo\AppData\Local\Programs\Python\Python312\Lib\site-packages\sklearn\base.py", line 1473, in wrapper
    return fit_method(estimator, *args, **kwargs)
           ^^^^^^^^^^^^^^^^^^^^^^^^^^^^^^^^^^^^^^
  File "C:\Users\Estudo\AppData\Local\Programs\Python\Python312\Lib\site-packages\sklearn\model_selection\_search.py", line 1019, in fit
    self._run_search(evaluate_candidates)
  File "C:\Users\Estudo\AppData\Local\Programs\Python\Python312\Lib\site-packages\sklearn\model_selection\_search.py", line 1573, in _run_search
    evaluate_candidates(ParameterGrid(self.param_grid))
  File "C:\Users\Estudo\AppData\Local\Programs\Python\Python312\Lib\site-packages\sklearn\model_selection\_search.py", line 996, in evaluate_candidates
    _warn_or_raise_about_fit_failures(out, self.error_score)
  File "C:\Users\Estudo\AppData\Local\Programs\Python\Python312\Lib\site-packages\sklearn\model_selection\_validation.py", line 529, in _warn_or_raise_about_fit_failures
    raise ValueError(all_fits_failed_message)
ValueError: 
All the 45 fits failed.
It is very likely that your model is misconfigured.
You can try to debug the error by setting error_score='raise'.

Below are more details about the failures:
--------------------------------------------------------------------------------
15 fits failed with the following error:
Traceback (most recent call last):
  File "C:\Users\Estudo\AppData\Local\Programs\Python\Python312\Lib\site-packages\sklearn\model_selection\_validation.py", line 888, in _fit_and_score
    estimator.fit(X_train, y_train, **fit_params)
  File "C:\Users\Estudo\AppData\Local\Programs\Python\Python312\Lib\site-packages\sklearn\base.py", line 1466, in wrapper
    estimator._validate_params()
  File "C:\Users\Estudo\AppData\Local\Programs\Python\Python312\Lib\site-packages\sklearn\base.py", line 666, in _validate_params
    validate_parameter_constraints(
  File "C:\Users\Estudo\AppData\Local\Programs\Python\Python312\Lib\site-packages\sklearn\utils\_param_validation.py", line 95, in validate_parameter_constraints
    raise InvalidParameterError(
sklearn.utils._param_validation.InvalidParameterError: The 'learning_rate' parameter of MLPClassifier must be a str among {'adaptive', 'invscaling', 'constant'}. Got 300 instead.

--------------------------------------------------------------------------------
15 fits failed with the following error:
Traceback (most recent call last):
  File "C:\Users\Estudo\AppData\Local\Programs\Python\Python312\Lib\site-packages\sklearn\model_selection\_validation.py", line 888, in _fit_and_score
    estimator.fit(X_train, y_train, **fit_params)
  File "C:\Users\Estudo\AppData\Local\Programs\Python\Python312\Lib\site-packages\sklearn\base.py", line 1466, in wrapper
    estimator._validate_params()
  File "C:\Users\Estudo\AppData\Local\Programs\Python\Python312\Lib\site-packages\sklearn\base.py", line 666, in _validate_params
    validate_parameter_constraints(
  File "C:\Users\Estudo\AppData\Local\Programs\Python\Python312\Lib\site-packages\sklearn\utils\_param_validation.py", line 95, in validate_parameter_constraints
    raise InvalidParameterError(
sklearn.utils._param_validation.InvalidParameterError: The 'learning_rate' parameter of MLPClassifier must be a str among {'adaptive', 'invscaling', 'constant'}. Got 400 instead.

--------------------------------------------------------------------------------
15 fits failed with the following error:
Traceback (most recent call last):
  File "C:\Users\Estudo\AppData\Local\Programs\Python\Python312\Lib\site-packages\sklearn\model_selection\_validation.py", line 888, in _fit_and_score
    estimator.fit(X_train, y_train, **fit_params)
  File "C:\Users\Estudo\AppData\Local\Programs\Python\Python312\Lib\site-packages\sklearn\base.py", line 1466, in wrapper
    estimator._validate_params()
  File "C:\Users\Estudo\AppData\Local\Programs\Python\Python312\Lib\site-packages\sklearn\base.py", line 666, in _validate_params
    validate_parameter_constraints(
  File "C:\Users\Estudo\AppData\Local\Programs\Python\Python312\Lib\site-packages\sklearn\utils\_param_validation.py", line 95, in validate_parameter_constraints
    raise InvalidParameterError(
sklearn.utils._param_validation.InvalidParameterError: The 'learning_rate' parameter of MLPClassifier must be a str among {'adaptive', 'invscaling', 'constant'}. Got 500 instead.

Traceback (most recent call last):
  File "C:\Users\Estudo\Documents\Best-Classification-AI-testing\code\program_analysis.py", line 342, in <module>
    analysis = Analysis(given_dataset, given_technique, given_optimization, given_cross_validation, given_model)
               ^^^^^^^^^^^^^^^^^^^^^^^^^^^^^^^^^^^^^^^^^^^^^^^^^^^^^^^^^^^^^^^^^^^^^^^^^^^^^^^^^^^^^^^^^^^^^^^^^
  File "C:\Users\Estudo\Documents\Best-Classification-AI-testing\code\program_analysis.py", line 44, in __init__
    performed = PerformAnalysis(technique, model, optimization, prepared.X_train, \
                ^^^^^^^^^^^^^^^^^^^^^^^^^^^^^^^^^^^^^^^^^^^^^^^^^^^^^^^^^^^^^^^^^^^
  File "C:\Users\Estudo\Documents\Best-Classification-AI-testing\code\program_analysis.py", line 125, in __init__
    self.select_model(model, optimization)
  File "C:\Users\Estudo\Documents\Best-Classification-AI-testing\code\program_analysis.py", line 254, in select_model
    self.get_metrics(optimized_model)
  File "C:\Users\Estudo\Documents\Best-Classification-AI-testing\code\program_analysis.py", line 257, in get_metrics
    classifier.fit(self.X_train, self.y_train)
  File "C:\Users\Estudo\AppData\Local\Programs\Python\Python312\Lib\site-packages\sklearn\base.py", line 1473, in wrapper
    return fit_method(estimator, *args, **kwargs)
           ^^^^^^^^^^^^^^^^^^^^^^^^^^^^^^^^^^^^^^
  File "C:\Users\Estudo\AppData\Local\Programs\Python\Python312\Lib\site-packages\sklearn\model_selection\_search.py", line 1019, in fit
    self._run_search(evaluate_candidates)
  File "C:\Users\Estudo\AppData\Local\Programs\Python\Python312\Lib\site-packages\sklearn\model_selection\_search.py", line 1573, in _run_search
    evaluate_candidates(ParameterGrid(self.param_grid))
  File "C:\Users\Estudo\AppData\Local\Programs\Python\Python312\Lib\site-packages\sklearn\model_selection\_search.py", line 996, in evaluate_candidates
    _warn_or_raise_about_fit_failures(out, self.error_score)
  File "C:\Users\Estudo\AppData\Local\Programs\Python\Python312\Lib\site-packages\sklearn\model_selection\_validation.py", line 529, in _warn_or_raise_about_fit_failures
    raise ValueError(all_fits_failed_message)
ValueError: 
All the 45 fits failed.
It is very likely that your model is misconfigured.
You can try to debug the error by setting error_score='raise'.

Below are more details about the failures:
--------------------------------------------------------------------------------
15 fits failed with the following error:
Traceback (most recent call last):
  File "C:\Users\Estudo\AppData\Local\Programs\Python\Python312\Lib\site-packages\sklearn\model_selection\_validation.py", line 888, in _fit_and_score
    estimator.fit(X_train, y_train, **fit_params)
  File "C:\Users\Estudo\AppData\Local\Programs\Python\Python312\Lib\site-packages\sklearn\base.py", line 1466, in wrapper
    estimator._validate_params()
  File "C:\Users\Estudo\AppData\Local\Programs\Python\Python312\Lib\site-packages\sklearn\base.py", line 666, in _validate_params
    validate_parameter_constraints(
  File "C:\Users\Estudo\AppData\Local\Programs\Python\Python312\Lib\site-packages\sklearn\utils\_param_validation.py", line 95, in validate_parameter_constraints
    raise InvalidParameterError(
sklearn.utils._param_validation.InvalidParameterError: The 'learning_rate' parameter of MLPClassifier must be a str among {'constant', 'invscaling', 'adaptive'}. Got 300 instead.

--------------------------------------------------------------------------------
15 fits failed with the following error:
Traceback (most recent call last):
  File "C:\Users\Estudo\AppData\Local\Programs\Python\Python312\Lib\site-packages\sklearn\model_selection\_validation.py", line 888, in _fit_and_score
    estimator.fit(X_train, y_train, **fit_params)
  File "C:\Users\Estudo\AppData\Local\Programs\Python\Python312\Lib\site-packages\sklearn\base.py", line 1466, in wrapper
    estimator._validate_params()
  File "C:\Users\Estudo\AppData\Local\Programs\Python\Python312\Lib\site-packages\sklearn\base.py", line 666, in _validate_params
    validate_parameter_constraints(
  File "C:\Users\Estudo\AppData\Local\Programs\Python\Python312\Lib\site-packages\sklearn\utils\_param_validation.py", line 95, in validate_parameter_constraints
    raise InvalidParameterError(
sklearn.utils._param_validation.InvalidParameterError: The 'learning_rate' parameter of MLPClassifier must be a str among {'constant', 'invscaling', 'adaptive'}. Got 400 instead.

--------------------------------------------------------------------------------
15 fits failed with the following error:
Traceback (most recent call last):
  File "C:\Users\Estudo\AppData\Local\Programs\Python\Python312\Lib\site-packages\sklearn\model_selection\_validation.py", line 888, in _fit_and_score
    estimator.fit(X_train, y_train, **fit_params)
  File "C:\Users\Estudo\AppData\Local\Programs\Python\Python312\Lib\site-packages\sklearn\base.py", line 1466, in wrapper
    estimator._validate_params()
  File "C:\Users\Estudo\AppData\Local\Programs\Python\Python312\Lib\site-packages\sklearn\base.py", line 666, in _validate_params
    validate_parameter_constraints(
  File "C:\Users\Estudo\AppData\Local\Programs\Python\Python312\Lib\site-packages\sklearn\utils\_param_validation.py", line 95, in validate_parameter_constraints
    raise InvalidParameterError(
sklearn.utils._param_validation.InvalidParameterError: The 'learning_rate' parameter of MLPClassifier must be a str among {'constant', 'invscaling', 'adaptive'}. Got 500 instead.

Traceback (most recent call last):
  File "C:\Users\Estudo\Documents\Best-Classification-AI-testing\code\program_analysis.py", line 342, in <module>
    analysis = Analysis(given_dataset, given_technique, given_optimization, given_cross_validation, given_model)
               ^^^^^^^^^^^^^^^^^^^^^^^^^^^^^^^^^^^^^^^^^^^^^^^^^^^^^^^^^^^^^^^^^^^^^^^^^^^^^^^^^^^^^^^^^^^^^^^^^
  File "C:\Users\Estudo\Documents\Best-Classification-AI-testing\code\program_analysis.py", line 44, in __init__
    performed = PerformAnalysis(technique, model, optimization, prepared.X_train, \
                ^^^^^^^^^^^^^^^^^^^^^^^^^^^^^^^^^^^^^^^^^^^^^^^^^^^^^^^^^^^^^^^^^^^
  File "C:\Users\Estudo\Documents\Best-Classification-AI-testing\code\program_analysis.py", line 125, in __init__
    self.select_model(model, optimization)
  File "C:\Users\Estudo\Documents\Best-Classification-AI-testing\code\program_analysis.py", line 254, in select_model
    self.get_metrics(optimized_model)
  File "C:\Users\Estudo\Documents\Best-Classification-AI-testing\code\program_analysis.py", line 257, in get_metrics
    classifier.fit(self.X_train, self.y_train)
  File "C:\Users\Estudo\AppData\Local\Programs\Python\Python312\Lib\site-packages\sklearn\base.py", line 1473, in wrapper
    return fit_method(estimator, *args, **kwargs)
           ^^^^^^^^^^^^^^^^^^^^^^^^^^^^^^^^^^^^^^
  File "C:\Users\Estudo\AppData\Local\Programs\Python\Python312\Lib\site-packages\sklearn\model_selection\_search.py", line 1019, in fit
    self._run_search(evaluate_candidates)
  File "C:\Users\Estudo\AppData\Local\Programs\Python\Python312\Lib\site-packages\sklearn\model_selection\_search.py", line 1573, in _run_search
    evaluate_candidates(ParameterGrid(self.param_grid))
  File "C:\Users\Estudo\AppData\Local\Programs\Python\Python312\Lib\site-packages\sklearn\model_selection\_search.py", line 996, in evaluate_candidates
    _warn_or_raise_about_fit_failures(out, self.error_score)
  File "C:\Users\Estudo\AppData\Local\Programs\Python\Python312\Lib\site-packages\sklearn\model_selection\_validation.py", line 529, in _warn_or_raise_about_fit_failures
    raise ValueError(all_fits_failed_message)
ValueError: 
All the 45 fits failed.
It is very likely that your model is misconfigured.
You can try to debug the error by setting error_score='raise'.

Below are more details about the failures:
--------------------------------------------------------------------------------
15 fits failed with the following error:
Traceback (most recent call last):
  File "C:\Users\Estudo\AppData\Local\Programs\Python\Python312\Lib\site-packages\sklearn\model_selection\_validation.py", line 888, in _fit_and_score
    estimator.fit(X_train, y_train, **fit_params)
  File "C:\Users\Estudo\AppData\Local\Programs\Python\Python312\Lib\site-packages\sklearn\base.py", line 1466, in wrapper
    estimator._validate_params()
  File "C:\Users\Estudo\AppData\Local\Programs\Python\Python312\Lib\site-packages\sklearn\base.py", line 666, in _validate_params
    validate_parameter_constraints(
  File "C:\Users\Estudo\AppData\Local\Programs\Python\Python312\Lib\site-packages\sklearn\utils\_param_validation.py", line 95, in validate_parameter_constraints
    raise InvalidParameterError(
sklearn.utils._param_validation.InvalidParameterError: The 'learning_rate' parameter of MLPClassifier must be a str among {'constant', 'invscaling', 'adaptive'}. Got 300 instead.

--------------------------------------------------------------------------------
15 fits failed with the following error:
Traceback (most recent call last):
  File "C:\Users\Estudo\AppData\Local\Programs\Python\Python312\Lib\site-packages\sklearn\model_selection\_validation.py", line 888, in _fit_and_score
    estimator.fit(X_train, y_train, **fit_params)
  File "C:\Users\Estudo\AppData\Local\Programs\Python\Python312\Lib\site-packages\sklearn\base.py", line 1466, in wrapper
    estimator._validate_params()
  File "C:\Users\Estudo\AppData\Local\Programs\Python\Python312\Lib\site-packages\sklearn\base.py", line 666, in _validate_params
    validate_parameter_constraints(
  File "C:\Users\Estudo\AppData\Local\Programs\Python\Python312\Lib\site-packages\sklearn\utils\_param_validation.py", line 95, in validate_parameter_constraints
    raise InvalidParameterError(
sklearn.utils._param_validation.InvalidParameterError: The 'learning_rate' parameter of MLPClassifier must be a str among {'constant', 'invscaling', 'adaptive'}. Got 400 instead.

--------------------------------------------------------------------------------
15 fits failed with the following error:
Traceback (most recent call last):
  File "C:\Users\Estudo\AppData\Local\Programs\Python\Python312\Lib\site-packages\sklearn\model_selection\_validation.py", line 888, in _fit_and_score
    estimator.fit(X_train, y_train, **fit_params)
  File "C:\Users\Estudo\AppData\Local\Programs\Python\Python312\Lib\site-packages\sklearn\base.py", line 1466, in wrapper
    estimator._validate_params()
  File "C:\Users\Estudo\AppData\Local\Programs\Python\Python312\Lib\site-packages\sklearn\base.py", line 666, in _validate_params
    validate_parameter_constraints(
  File "C:\Users\Estudo\AppData\Local\Programs\Python\Python312\Lib\site-packages\sklearn\utils\_param_validation.py", line 95, in validate_parameter_constraints
    raise InvalidParameterError(
sklearn.utils._param_validation.InvalidParameterError: The 'learning_rate' parameter of MLPClassifier must be a str among {'constant', 'invscaling', 'adaptive'}. Got 500 instead.

Traceback (most recent call last):
  File "C:\Users\Estudo\Documents\Best-Classification-AI-testing\code\program_analysis.py", line 342, in <module>
    analysis = Analysis(given_dataset, given_technique, given_optimization, given_cross_validation, given_model)
               ^^^^^^^^^^^^^^^^^^^^^^^^^^^^^^^^^^^^^^^^^^^^^^^^^^^^^^^^^^^^^^^^^^^^^^^^^^^^^^^^^^^^^^^^^^^^^^^^^
  File "C:\Users\Estudo\Documents\Best-Classification-AI-testing\code\program_analysis.py", line 44, in __init__
    performed = PerformAnalysis(technique, model, optimization, prepared.X_train, \
                ^^^^^^^^^^^^^^^^^^^^^^^^^^^^^^^^^^^^^^^^^^^^^^^^^^^^^^^^^^^^^^^^^^^
  File "C:\Users\Estudo\Documents\Best-Classification-AI-testing\code\program_analysis.py", line 125, in __init__
    self.select_model(model, optimization)
  File "C:\Users\Estudo\Documents\Best-Classification-AI-testing\code\program_analysis.py", line 254, in select_model
    self.get_metrics(optimized_model)
  File "C:\Users\Estudo\Documents\Best-Classification-AI-testing\code\program_analysis.py", line 257, in get_metrics
    classifier.fit(self.X_train, self.y_train)
  File "C:\Users\Estudo\AppData\Local\Programs\Python\Python312\Lib\site-packages\sklearn\base.py", line 1473, in wrapper
    return fit_method(estimator, *args, **kwargs)
           ^^^^^^^^^^^^^^^^^^^^^^^^^^^^^^^^^^^^^^
  File "C:\Users\Estudo\AppData\Local\Programs\Python\Python312\Lib\site-packages\sklearn\model_selection\_search.py", line 1019, in fit
    self._run_search(evaluate_candidates)
  File "C:\Users\Estudo\AppData\Local\Programs\Python\Python312\Lib\site-packages\sklearn\model_selection\_search.py", line 1573, in _run_search
    evaluate_candidates(ParameterGrid(self.param_grid))
  File "C:\Users\Estudo\AppData\Local\Programs\Python\Python312\Lib\site-packages\sklearn\model_selection\_search.py", line 996, in evaluate_candidates
    _warn_or_raise_about_fit_failures(out, self.error_score)
  File "C:\Users\Estudo\AppData\Local\Programs\Python\Python312\Lib\site-packages\sklearn\model_selection\_validation.py", line 529, in _warn_or_raise_about_fit_failures
    raise ValueError(all_fits_failed_message)
ValueError: 
All the 45 fits failed.
It is very likely that your model is misconfigured.
You can try to debug the error by setting error_score='raise'.

Below are more details about the failures:
--------------------------------------------------------------------------------
15 fits failed with the following error:
Traceback (most recent call last):
  File "C:\Users\Estudo\AppData\Local\Programs\Python\Python312\Lib\site-packages\sklearn\model_selection\_validation.py", line 888, in _fit_and_score
    estimator.fit(X_train, y_train, **fit_params)
  File "C:\Users\Estudo\AppData\Local\Programs\Python\Python312\Lib\site-packages\sklearn\base.py", line 1466, in wrapper
    estimator._validate_params()
  File "C:\Users\Estudo\AppData\Local\Programs\Python\Python312\Lib\site-packages\sklearn\base.py", line 666, in _validate_params
    validate_parameter_constraints(
  File "C:\Users\Estudo\AppData\Local\Programs\Python\Python312\Lib\site-packages\sklearn\utils\_param_validation.py", line 95, in validate_parameter_constraints
    raise InvalidParameterError(
sklearn.utils._param_validation.InvalidParameterError: The 'learning_rate' parameter of MLPClassifier must be a str among {'constant', 'invscaling', 'adaptive'}. Got 300 instead.

--------------------------------------------------------------------------------
15 fits failed with the following error:
Traceback (most recent call last):
  File "C:\Users\Estudo\AppData\Local\Programs\Python\Python312\Lib\site-packages\sklearn\model_selection\_validation.py", line 888, in _fit_and_score
    estimator.fit(X_train, y_train, **fit_params)
  File "C:\Users\Estudo\AppData\Local\Programs\Python\Python312\Lib\site-packages\sklearn\base.py", line 1466, in wrapper
    estimator._validate_params()
  File "C:\Users\Estudo\AppData\Local\Programs\Python\Python312\Lib\site-packages\sklearn\base.py", line 666, in _validate_params
    validate_parameter_constraints(
  File "C:\Users\Estudo\AppData\Local\Programs\Python\Python312\Lib\site-packages\sklearn\utils\_param_validation.py", line 95, in validate_parameter_constraints
    raise InvalidParameterError(
sklearn.utils._param_validation.InvalidParameterError: The 'learning_rate' parameter of MLPClassifier must be a str among {'constant', 'invscaling', 'adaptive'}. Got 400 instead.

--------------------------------------------------------------------------------
15 fits failed with the following error:
Traceback (most recent call last):
  File "C:\Users\Estudo\AppData\Local\Programs\Python\Python312\Lib\site-packages\sklearn\model_selection\_validation.py", line 888, in _fit_and_score
    estimator.fit(X_train, y_train, **fit_params)
  File "C:\Users\Estudo\AppData\Local\Programs\Python\Python312\Lib\site-packages\sklearn\base.py", line 1466, in wrapper
    estimator._validate_params()
  File "C:\Users\Estudo\AppData\Local\Programs\Python\Python312\Lib\site-packages\sklearn\base.py", line 666, in _validate_params
    validate_parameter_constraints(
  File "C:\Users\Estudo\AppData\Local\Programs\Python\Python312\Lib\site-packages\sklearn\utils\_param_validation.py", line 95, in validate_parameter_constraints
    raise InvalidParameterError(
sklearn.utils._param_validation.InvalidParameterError: The 'learning_rate' parameter of MLPClassifier must be a str among {'constant', 'invscaling', 'adaptive'}. Got 500 instead.

Traceback (most recent call last):
  File "C:\Users\Estudo\Documents\Best-Classification-AI-testing\code\program_analysis.py", line 342, in <module>
    analysis = Analysis(given_dataset, given_technique, given_optimization, given_cross_validation, given_model)
               ^^^^^^^^^^^^^^^^^^^^^^^^^^^^^^^^^^^^^^^^^^^^^^^^^^^^^^^^^^^^^^^^^^^^^^^^^^^^^^^^^^^^^^^^^^^^^^^^^
  File "C:\Users\Estudo\Documents\Best-Classification-AI-testing\code\program_analysis.py", line 44, in __init__
    performed = PerformAnalysis(technique, model, optimization, prepared.X_train, \
                ^^^^^^^^^^^^^^^^^^^^^^^^^^^^^^^^^^^^^^^^^^^^^^^^^^^^^^^^^^^^^^^^^^^
  File "C:\Users\Estudo\Documents\Best-Classification-AI-testing\code\program_analysis.py", line 125, in __init__
    self.select_model(model, optimization)
  File "C:\Users\Estudo\Documents\Best-Classification-AI-testing\code\program_analysis.py", line 254, in select_model
    self.get_metrics(optimized_model)
  File "C:\Users\Estudo\Documents\Best-Classification-AI-testing\code\program_analysis.py", line 257, in get_metrics
    classifier.fit(self.X_train, self.y_train)
  File "C:\Users\Estudo\AppData\Local\Programs\Python\Python312\Lib\site-packages\sklearn\base.py", line 1473, in wrapper
    return fit_method(estimator, *args, **kwargs)
           ^^^^^^^^^^^^^^^^^^^^^^^^^^^^^^^^^^^^^^
  File "C:\Users\Estudo\AppData\Local\Programs\Python\Python312\Lib\site-packages\sklearn\model_selection\_search.py", line 1019, in fit
    self._run_search(evaluate_candidates)
  File "C:\Users\Estudo\AppData\Local\Programs\Python\Python312\Lib\site-packages\sklearn\model_selection\_search.py", line 1573, in _run_search
    evaluate_candidates(ParameterGrid(self.param_grid))
  File "C:\Users\Estudo\AppData\Local\Programs\Python\Python312\Lib\site-packages\sklearn\model_selection\_search.py", line 996, in evaluate_candidates
    _warn_or_raise_about_fit_failures(out, self.error_score)
  File "C:\Users\Estudo\AppData\Local\Programs\Python\Python312\Lib\site-packages\sklearn\model_selection\_validation.py", line 529, in _warn_or_raise_about_fit_failures
    raise ValueError(all_fits_failed_message)
ValueError: 
All the 45 fits failed.
It is very likely that your model is misconfigured.
You can try to debug the error by setting error_score='raise'.

Below are more details about the failures:
--------------------------------------------------------------------------------
15 fits failed with the following error:
Traceback (most recent call last):
  File "C:\Users\Estudo\AppData\Local\Programs\Python\Python312\Lib\site-packages\sklearn\model_selection\_validation.py", line 888, in _fit_and_score
    estimator.fit(X_train, y_train, **fit_params)
  File "C:\Users\Estudo\AppData\Local\Programs\Python\Python312\Lib\site-packages\sklearn\base.py", line 1466, in wrapper
    estimator._validate_params()
  File "C:\Users\Estudo\AppData\Local\Programs\Python\Python312\Lib\site-packages\sklearn\base.py", line 666, in _validate_params
    validate_parameter_constraints(
  File "C:\Users\Estudo\AppData\Local\Programs\Python\Python312\Lib\site-packages\sklearn\utils\_param_validation.py", line 95, in validate_parameter_constraints
    raise InvalidParameterError(
sklearn.utils._param_validation.InvalidParameterError: The 'learning_rate' parameter of MLPClassifier must be a str among {'adaptive', 'constant', 'invscaling'}. Got 300 instead.

--------------------------------------------------------------------------------
15 fits failed with the following error:
Traceback (most recent call last):
  File "C:\Users\Estudo\AppData\Local\Programs\Python\Python312\Lib\site-packages\sklearn\model_selection\_validation.py", line 888, in _fit_and_score
    estimator.fit(X_train, y_train, **fit_params)
  File "C:\Users\Estudo\AppData\Local\Programs\Python\Python312\Lib\site-packages\sklearn\base.py", line 1466, in wrapper
    estimator._validate_params()
  File "C:\Users\Estudo\AppData\Local\Programs\Python\Python312\Lib\site-packages\sklearn\base.py", line 666, in _validate_params
    validate_parameter_constraints(
  File "C:\Users\Estudo\AppData\Local\Programs\Python\Python312\Lib\site-packages\sklearn\utils\_param_validation.py", line 95, in validate_parameter_constraints
    raise InvalidParameterError(
sklearn.utils._param_validation.InvalidParameterError: The 'learning_rate' parameter of MLPClassifier must be a str among {'adaptive', 'constant', 'invscaling'}. Got 400 instead.

--------------------------------------------------------------------------------
15 fits failed with the following error:
Traceback (most recent call last):
  File "C:\Users\Estudo\AppData\Local\Programs\Python\Python312\Lib\site-packages\sklearn\model_selection\_validation.py", line 888, in _fit_and_score
    estimator.fit(X_train, y_train, **fit_params)
  File "C:\Users\Estudo\AppData\Local\Programs\Python\Python312\Lib\site-packages\sklearn\base.py", line 1466, in wrapper
    estimator._validate_params()
  File "C:\Users\Estudo\AppData\Local\Programs\Python\Python312\Lib\site-packages\sklearn\base.py", line 666, in _validate_params
    validate_parameter_constraints(
  File "C:\Users\Estudo\AppData\Local\Programs\Python\Python312\Lib\site-packages\sklearn\utils\_param_validation.py", line 95, in validate_parameter_constraints
    raise InvalidParameterError(
sklearn.utils._param_validation.InvalidParameterError: The 'learning_rate' parameter of MLPClassifier must be a str among {'adaptive', 'constant', 'invscaling'}. Got 500 instead.

Traceback (most recent call last):
  File "C:\Users\Estudo\Documents\Best-Classification-AI-testing\code\program_analysis.py", line 342, in <module>
    analysis = Analysis(given_dataset, given_technique, given_optimization, given_cross_validation, given_model)
               ^^^^^^^^^^^^^^^^^^^^^^^^^^^^^^^^^^^^^^^^^^^^^^^^^^^^^^^^^^^^^^^^^^^^^^^^^^^^^^^^^^^^^^^^^^^^^^^^^
  File "C:\Users\Estudo\Documents\Best-Classification-AI-testing\code\program_analysis.py", line 44, in __init__
    performed = PerformAnalysis(technique, model, optimization, prepared.X_train, \
                ^^^^^^^^^^^^^^^^^^^^^^^^^^^^^^^^^^^^^^^^^^^^^^^^^^^^^^^^^^^^^^^^^^^
  File "C:\Users\Estudo\Documents\Best-Classification-AI-testing\code\program_analysis.py", line 125, in __init__
    self.select_model(model, optimization)
  File "C:\Users\Estudo\Documents\Best-Classification-AI-testing\code\program_analysis.py", line 254, in select_model
    self.get_metrics(optimized_model)
  File "C:\Users\Estudo\Documents\Best-Classification-AI-testing\code\program_analysis.py", line 257, in get_metrics
    classifier.fit(self.X_train, self.y_train)
  File "C:\Users\Estudo\AppData\Local\Programs\Python\Python312\Lib\site-packages\sklearn\base.py", line 1473, in wrapper
    return fit_method(estimator, *args, **kwargs)
           ^^^^^^^^^^^^^^^^^^^^^^^^^^^^^^^^^^^^^^
  File "C:\Users\Estudo\AppData\Local\Programs\Python\Python312\Lib\site-packages\sklearn\model_selection\_search.py", line 1019, in fit
    self._run_search(evaluate_candidates)
  File "C:\Users\Estudo\AppData\Local\Programs\Python\Python312\Lib\site-packages\sklearn\model_selection\_search.py", line 1573, in _run_search
    evaluate_candidates(ParameterGrid(self.param_grid))
  File "C:\Users\Estudo\AppData\Local\Programs\Python\Python312\Lib\site-packages\sklearn\model_selection\_search.py", line 996, in evaluate_candidates
    _warn_or_raise_about_fit_failures(out, self.error_score)
  File "C:\Users\Estudo\AppData\Local\Programs\Python\Python312\Lib\site-packages\sklearn\model_selection\_validation.py", line 529, in _warn_or_raise_about_fit_failures
    raise ValueError(all_fits_failed_message)
ValueError: 
All the 45 fits failed.
It is very likely that your model is misconfigured.
You can try to debug the error by setting error_score='raise'.

Below are more details about the failures:
--------------------------------------------------------------------------------
15 fits failed with the following error:
Traceback (most recent call last):
  File "C:\Users\Estudo\AppData\Local\Programs\Python\Python312\Lib\site-packages\sklearn\model_selection\_validation.py", line 888, in _fit_and_score
    estimator.fit(X_train, y_train, **fit_params)
  File "C:\Users\Estudo\AppData\Local\Programs\Python\Python312\Lib\site-packages\sklearn\base.py", line 1466, in wrapper
    estimator._validate_params()
  File "C:\Users\Estudo\AppData\Local\Programs\Python\Python312\Lib\site-packages\sklearn\base.py", line 666, in _validate_params
    validate_parameter_constraints(
  File "C:\Users\Estudo\AppData\Local\Programs\Python\Python312\Lib\site-packages\sklearn\utils\_param_validation.py", line 95, in validate_parameter_constraints
    raise InvalidParameterError(
sklearn.utils._param_validation.InvalidParameterError: The 'learning_rate' parameter of MLPClassifier must be a str among {'invscaling', 'constant', 'adaptive'}. Got 300 instead.

--------------------------------------------------------------------------------
15 fits failed with the following error:
Traceback (most recent call last):
  File "C:\Users\Estudo\AppData\Local\Programs\Python\Python312\Lib\site-packages\sklearn\model_selection\_validation.py", line 888, in _fit_and_score
    estimator.fit(X_train, y_train, **fit_params)
  File "C:\Users\Estudo\AppData\Local\Programs\Python\Python312\Lib\site-packages\sklearn\base.py", line 1466, in wrapper
    estimator._validate_params()
  File "C:\Users\Estudo\AppData\Local\Programs\Python\Python312\Lib\site-packages\sklearn\base.py", line 666, in _validate_params
    validate_parameter_constraints(
  File "C:\Users\Estudo\AppData\Local\Programs\Python\Python312\Lib\site-packages\sklearn\utils\_param_validation.py", line 95, in validate_parameter_constraints
    raise InvalidParameterError(
sklearn.utils._param_validation.InvalidParameterError: The 'learning_rate' parameter of MLPClassifier must be a str among {'invscaling', 'constant', 'adaptive'}. Got 400 instead.

--------------------------------------------------------------------------------
15 fits failed with the following error:
Traceback (most recent call last):
  File "C:\Users\Estudo\AppData\Local\Programs\Python\Python312\Lib\site-packages\sklearn\model_selection\_validation.py", line 888, in _fit_and_score
    estimator.fit(X_train, y_train, **fit_params)
  File "C:\Users\Estudo\AppData\Local\Programs\Python\Python312\Lib\site-packages\sklearn\base.py", line 1466, in wrapper
    estimator._validate_params()
  File "C:\Users\Estudo\AppData\Local\Programs\Python\Python312\Lib\site-packages\sklearn\base.py", line 666, in _validate_params
    validate_parameter_constraints(
  File "C:\Users\Estudo\AppData\Local\Programs\Python\Python312\Lib\site-packages\sklearn\utils\_param_validation.py", line 95, in validate_parameter_constraints
    raise InvalidParameterError(
sklearn.utils._param_validation.InvalidParameterError: The 'learning_rate' parameter of MLPClassifier must be a str among {'invscaling', 'constant', 'adaptive'}. Got 500 instead.

Traceback (most recent call last):
  File "C:\Users\Estudo\Documents\Best-Classification-AI-testing\code\program_analysis.py", line 342, in <module>
    analysis = Analysis(given_dataset, given_technique, given_optimization, given_cross_validation, given_model)
               ^^^^^^^^^^^^^^^^^^^^^^^^^^^^^^^^^^^^^^^^^^^^^^^^^^^^^^^^^^^^^^^^^^^^^^^^^^^^^^^^^^^^^^^^^^^^^^^^^
  File "C:\Users\Estudo\Documents\Best-Classification-AI-testing\code\program_analysis.py", line 44, in __init__
    performed = PerformAnalysis(technique, model, optimization, prepared.X_train, \
                ^^^^^^^^^^^^^^^^^^^^^^^^^^^^^^^^^^^^^^^^^^^^^^^^^^^^^^^^^^^^^^^^^^^
  File "C:\Users\Estudo\Documents\Best-Classification-AI-testing\code\program_analysis.py", line 125, in __init__
    self.select_model(model, optimization)
  File "C:\Users\Estudo\Documents\Best-Classification-AI-testing\code\program_analysis.py", line 254, in select_model
    self.get_metrics(optimized_model)
  File "C:\Users\Estudo\Documents\Best-Classification-AI-testing\code\program_analysis.py", line 257, in get_metrics
    classifier.fit(self.X_train, self.y_train)
  File "C:\Users\Estudo\AppData\Local\Programs\Python\Python312\Lib\site-packages\sklearn\base.py", line 1473, in wrapper
    return fit_method(estimator, *args, **kwargs)
           ^^^^^^^^^^^^^^^^^^^^^^^^^^^^^^^^^^^^^^
  File "C:\Users\Estudo\AppData\Local\Programs\Python\Python312\Lib\site-packages\sklearn\model_selection\_search.py", line 1019, in fit
    self._run_search(evaluate_candidates)
  File "C:\Users\Estudo\AppData\Local\Programs\Python\Python312\Lib\site-packages\sklearn\model_selection\_search.py", line 1573, in _run_search
    evaluate_candidates(ParameterGrid(self.param_grid))
  File "C:\Users\Estudo\AppData\Local\Programs\Python\Python312\Lib\site-packages\sklearn\model_selection\_search.py", line 996, in evaluate_candidates
    _warn_or_raise_about_fit_failures(out, self.error_score)
  File "C:\Users\Estudo\AppData\Local\Programs\Python\Python312\Lib\site-packages\sklearn\model_selection\_validation.py", line 529, in _warn_or_raise_about_fit_failures
    raise ValueError(all_fits_failed_message)
ValueError: 
All the 45 fits failed.
It is very likely that your model is misconfigured.
You can try to debug the error by setting error_score='raise'.

Below are more details about the failures:
--------------------------------------------------------------------------------
15 fits failed with the following error:
Traceback (most recent call last):
  File "C:\Users\Estudo\AppData\Local\Programs\Python\Python312\Lib\site-packages\sklearn\model_selection\_validation.py", line 888, in _fit_and_score
    estimator.fit(X_train, y_train, **fit_params)
  File "C:\Users\Estudo\AppData\Local\Programs\Python\Python312\Lib\site-packages\sklearn\base.py", line 1466, in wrapper
    estimator._validate_params()
  File "C:\Users\Estudo\AppData\Local\Programs\Python\Python312\Lib\site-packages\sklearn\base.py", line 666, in _validate_params
    validate_parameter_constraints(
  File "C:\Users\Estudo\AppData\Local\Programs\Python\Python312\Lib\site-packages\sklearn\utils\_param_validation.py", line 95, in validate_parameter_constraints
    raise InvalidParameterError(
sklearn.utils._param_validation.InvalidParameterError: The 'learning_rate' parameter of MLPClassifier must be a str among {'invscaling', 'constant', 'adaptive'}. Got 300 instead.

--------------------------------------------------------------------------------
15 fits failed with the following error:
Traceback (most recent call last):
  File "C:\Users\Estudo\AppData\Local\Programs\Python\Python312\Lib\site-packages\sklearn\model_selection\_validation.py", line 888, in _fit_and_score
    estimator.fit(X_train, y_train, **fit_params)
  File "C:\Users\Estudo\AppData\Local\Programs\Python\Python312\Lib\site-packages\sklearn\base.py", line 1466, in wrapper
    estimator._validate_params()
  File "C:\Users\Estudo\AppData\Local\Programs\Python\Python312\Lib\site-packages\sklearn\base.py", line 666, in _validate_params
    validate_parameter_constraints(
  File "C:\Users\Estudo\AppData\Local\Programs\Python\Python312\Lib\site-packages\sklearn\utils\_param_validation.py", line 95, in validate_parameter_constraints
    raise InvalidParameterError(
sklearn.utils._param_validation.InvalidParameterError: The 'learning_rate' parameter of MLPClassifier must be a str among {'invscaling', 'constant', 'adaptive'}. Got 400 instead.

--------------------------------------------------------------------------------
15 fits failed with the following error:
Traceback (most recent call last):
  File "C:\Users\Estudo\AppData\Local\Programs\Python\Python312\Lib\site-packages\sklearn\model_selection\_validation.py", line 888, in _fit_and_score
    estimator.fit(X_train, y_train, **fit_params)
  File "C:\Users\Estudo\AppData\Local\Programs\Python\Python312\Lib\site-packages\sklearn\base.py", line 1466, in wrapper
    estimator._validate_params()
  File "C:\Users\Estudo\AppData\Local\Programs\Python\Python312\Lib\site-packages\sklearn\base.py", line 666, in _validate_params
    validate_parameter_constraints(
  File "C:\Users\Estudo\AppData\Local\Programs\Python\Python312\Lib\site-packages\sklearn\utils\_param_validation.py", line 95, in validate_parameter_constraints
    raise InvalidParameterError(
sklearn.utils._param_validation.InvalidParameterError: The 'learning_rate' parameter of MLPClassifier must be a str among {'invscaling', 'constant', 'adaptive'}. Got 500 instead.

Traceback (most recent call last):
  File "C:\Users\Estudo\Documents\Best-Classification-AI-testing\code\program_analysis.py", line 342, in <module>
    analysis = Analysis(given_dataset, given_technique, given_optimization, given_cross_validation, given_model)
               ^^^^^^^^^^^^^^^^^^^^^^^^^^^^^^^^^^^^^^^^^^^^^^^^^^^^^^^^^^^^^^^^^^^^^^^^^^^^^^^^^^^^^^^^^^^^^^^^^
  File "C:\Users\Estudo\Documents\Best-Classification-AI-testing\code\program_analysis.py", line 44, in __init__
    performed = PerformAnalysis(technique, model, optimization, prepared.X_train, \
                ^^^^^^^^^^^^^^^^^^^^^^^^^^^^^^^^^^^^^^^^^^^^^^^^^^^^^^^^^^^^^^^^^^^
  File "C:\Users\Estudo\Documents\Best-Classification-AI-testing\code\program_analysis.py", line 125, in __init__
    self.select_model(model, optimization)
  File "C:\Users\Estudo\Documents\Best-Classification-AI-testing\code\program_analysis.py", line 254, in select_model
    self.get_metrics(optimized_model)
  File "C:\Users\Estudo\Documents\Best-Classification-AI-testing\code\program_analysis.py", line 257, in get_metrics
    classifier.fit(self.X_train, self.y_train)
  File "C:\Users\Estudo\AppData\Local\Programs\Python\Python312\Lib\site-packages\sklearn\base.py", line 1473, in wrapper
    return fit_method(estimator, *args, **kwargs)
           ^^^^^^^^^^^^^^^^^^^^^^^^^^^^^^^^^^^^^^
  File "C:\Users\Estudo\AppData\Local\Programs\Python\Python312\Lib\site-packages\sklearn\model_selection\_search.py", line 1019, in fit
    self._run_search(evaluate_candidates)
  File "C:\Users\Estudo\AppData\Local\Programs\Python\Python312\Lib\site-packages\sklearn\model_selection\_search.py", line 1573, in _run_search
    evaluate_candidates(ParameterGrid(self.param_grid))
  File "C:\Users\Estudo\AppData\Local\Programs\Python\Python312\Lib\site-packages\sklearn\model_selection\_search.py", line 996, in evaluate_candidates
    _warn_or_raise_about_fit_failures(out, self.error_score)
  File "C:\Users\Estudo\AppData\Local\Programs\Python\Python312\Lib\site-packages\sklearn\model_selection\_validation.py", line 529, in _warn_or_raise_about_fit_failures
    raise ValueError(all_fits_failed_message)
ValueError: 
All the 45 fits failed.
It is very likely that your model is misconfigured.
You can try to debug the error by setting error_score='raise'.

Below are more details about the failures:
--------------------------------------------------------------------------------
15 fits failed with the following error:
Traceback (most recent call last):
  File "C:\Users\Estudo\AppData\Local\Programs\Python\Python312\Lib\site-packages\sklearn\model_selection\_validation.py", line 888, in _fit_and_score
    estimator.fit(X_train, y_train, **fit_params)
  File "C:\Users\Estudo\AppData\Local\Programs\Python\Python312\Lib\site-packages\sklearn\base.py", line 1466, in wrapper
    estimator._validate_params()
  File "C:\Users\Estudo\AppData\Local\Programs\Python\Python312\Lib\site-packages\sklearn\base.py", line 666, in _validate_params
    validate_parameter_constraints(
  File "C:\Users\Estudo\AppData\Local\Programs\Python\Python312\Lib\site-packages\sklearn\utils\_param_validation.py", line 95, in validate_parameter_constraints
    raise InvalidParameterError(
sklearn.utils._param_validation.InvalidParameterError: The 'learning_rate' parameter of MLPClassifier must be a str among {'adaptive', 'constant', 'invscaling'}. Got 300 instead.

--------------------------------------------------------------------------------
15 fits failed with the following error:
Traceback (most recent call last):
  File "C:\Users\Estudo\AppData\Local\Programs\Python\Python312\Lib\site-packages\sklearn\model_selection\_validation.py", line 888, in _fit_and_score
    estimator.fit(X_train, y_train, **fit_params)
  File "C:\Users\Estudo\AppData\Local\Programs\Python\Python312\Lib\site-packages\sklearn\base.py", line 1466, in wrapper
    estimator._validate_params()
  File "C:\Users\Estudo\AppData\Local\Programs\Python\Python312\Lib\site-packages\sklearn\base.py", line 666, in _validate_params
    validate_parameter_constraints(
  File "C:\Users\Estudo\AppData\Local\Programs\Python\Python312\Lib\site-packages\sklearn\utils\_param_validation.py", line 95, in validate_parameter_constraints
    raise InvalidParameterError(
sklearn.utils._param_validation.InvalidParameterError: The 'learning_rate' parameter of MLPClassifier must be a str among {'adaptive', 'constant', 'invscaling'}. Got 400 instead.

--------------------------------------------------------------------------------
15 fits failed with the following error:
Traceback (most recent call last):
  File "C:\Users\Estudo\AppData\Local\Programs\Python\Python312\Lib\site-packages\sklearn\model_selection\_validation.py", line 888, in _fit_and_score
    estimator.fit(X_train, y_train, **fit_params)
  File "C:\Users\Estudo\AppData\Local\Programs\Python\Python312\Lib\site-packages\sklearn\base.py", line 1466, in wrapper
    estimator._validate_params()
  File "C:\Users\Estudo\AppData\Local\Programs\Python\Python312\Lib\site-packages\sklearn\base.py", line 666, in _validate_params
    validate_parameter_constraints(
  File "C:\Users\Estudo\AppData\Local\Programs\Python\Python312\Lib\site-packages\sklearn\utils\_param_validation.py", line 95, in validate_parameter_constraints
    raise InvalidParameterError(
sklearn.utils._param_validation.InvalidParameterError: The 'learning_rate' parameter of MLPClassifier must be a str among {'adaptive', 'constant', 'invscaling'}. Got 500 instead.

No Technique,DecisionTree,0.11635041236877441,0.9296875,0.9666666666666667
No Technique,DecisionTree,0.0982522964477539,0.9296875,1.0
No Technique,DecisionTree,0.07813096046447754,0.93359375,1.0
No Technique,DecisionTree,0.07009196281433105,0.94140625,0.9666666666666667
No Technique,DecisionTree,0.11143708229064941,0.93359375,1.0
No Technique,DecisionTree,0.12416601181030273,0.93359375,1.0
No Technique,DecisionTree,0.10503649711608887,0.79296875,1.0
No Technique,DecisionTree,0.12397336959838867,0.9375,1.0
No Technique,DecisionTree,0.08089232444763184,0.93359375,0.9666666666666667
No Technique,DecisionTree,0.09794783592224121,0.87890625,1.0
No Technique,DecisionTree,0.10765314102172852,0.93359375,1.0
No Technique,DecisionTree,0.09215283393859863,0.8828125,0.9666666666666667
No Technique,DecisionTree,0.06620001792907715,0.87890625,0.9666666666666667
No Technique,DecisionTree,0.06360816955566406,0.875,0.9666666666666667
No Technique,DecisionTree,0.10799241065979004,0.93359375,1.0
No Technique,DecisionTree,0.06628608703613281,0.87890625,0.9666666666666667
No Technique,DecisionTree,0.08885025978088379,0.93359375,0.9666666666666667
No Technique,DecisionTree,0.12090802192687988,0.9375,1.0
No Technique,DecisionTree,0.10831522941589355,0.9296875,0.9333333333333333
No Technique,DecisionTree,0.13895344734191895,0.9375,1.0
No Technique,RandomForest,28.030779361724854,2.1328125,1.0
No Technique,RandomForest,31.56334686279297,2.09375,1.0
No Technique,RandomForest,33.72146964073181,2.09375,1.0
No Technique,RandomForest,33.76058745384216,2.17578125,1.0
No Technique,RandomForest,19.854066133499146,2.23046875,1.0
No Technique,RandomForest,33.13531279563904,2.26171875,1.0
No Technique,RandomForest,34.8137104511261,2.37890625,1.0
No Technique,RandomForest,32.67070770263672,2.23046875,0.9666666666666667
No Technique,RandomForest,32.98844313621521,2.171875,1.0
No Technique,RandomForest,27.061002016067505,2.1875,1.0
No Technique,RandomForest,19.94706702232361,2.19921875,0.9666666666666667
No Technique,RandomForest,38.087459087371826,2.265625,1.0
No Technique,RandomForest,19.6558895111084,2.50390625,1.0
No Technique,RandomForest,34.18003821372986,2.1015625,1.0
No Technique,RandomForest,30.275744676589966,2.17578125,1.0
No Technique,RandomForest,32.719104528427124,2.1875,0.9666666666666667
No Technique,RandomForest,34.88262438774109,2.28515625,1.0
No Technique,RandomForest,32.77923583984375,2.2421875,1.0
No Technique,RandomForest,33.68539810180664,2.21484375,1.0
No Technique,RandomForest,32.24019908905029,2.1640625,1.0
No Technique,KNN,0.1250927448272705,1.02734375,1.0
No Technique,KNN,0.1261284351348877,1.015625,1.0
No Technique,KNN,0.13341403007507324,1.015625,1.0
No Technique,KNN,0.18207788467407227,1.01953125,1.0
No Technique,KNN,0.1305251121520996,1.078125,1.0
No Technique,KNN,0.16678667068481445,1.01171875,1.0
No Technique,KNN,0.12553930282592773,1.02734375,0.9666666666666667
No Technique,KNN,0.12991857528686523,1.046875,1.0
No Technique,KNN,0.13103985786437988,1.01171875,1.0
No Technique,KNN,0.13561582565307617,0.98828125,0.9666666666666667
No Technique,KNN,0.13520264625549316,1.046875,1.0
No Technique,KNN,0.19389653205871582,1.0,1.0
No Technique,KNN,0.20793676376342773,1.01171875,1.0
No Technique,KNN,0.16237902641296387,1.06640625,1.0
No Technique,KNN,0.1329641342163086,0.96484375,1.0
No Technique,KNN,0.12355709075927734,1.01171875,1.0
No Technique,KNN,0.22348475456237793,1.0234375,1.0
No Technique,KNN,0.1323080062866211,0.98828125,1.0
No Technique,KNN,0.13177800178527832,1.06640625,1.0
No Technique,KNN,0.12281680107116699,1.015625,1.0
No Technique,LogReg,0.17439532279968262,1.06640625,1.0
No Technique,LogReg,0.17523527145385742,1.05859375,1.0
No Technique,LogReg,0.18162250518798828,1.20703125,1.0
No Technique,LogReg,0.17320489883422852,1.0546875,1.0
No Technique,LogReg,0.17076587677001953,1.16015625,0.9666666666666667
No Technique,LogReg,0.17631030082702637,1.0234375,1.0
No Technique,LogReg,0.18998408317565918,1.20703125,1.0
No Technique,LogReg,0.1759343147277832,1.03125,0.9666666666666667
No Technique,LogReg,0.170013427734375,0.91796875,0.9666666666666667
No Technique,LogReg,0.17433691024780273,1.05859375,1.0
No Technique,LogReg,0.1944141387939453,0.99609375,1.0
No Technique,LogReg,0.17949461936950684,1.10546875,1.0
No Technique,LogReg,0.221482515335083,1.0625,0.9666666666666667
No Technique,LogReg,0.30137157440185547,1.0546875,1.0
No Technique,LogReg,0.17877554893493652,1.0703125,1.0
No Technique,LogReg,0.18045568466186523,1.0859375,0.9666666666666667
No Technique,LogReg,0.17383098602294922,1.125,0.9666666666666667
No Technique,LogReg,0.1854383945465088,1.14453125,1.0
No Technique,LogReg,0.22654342651367188,1.15234375,1.0
No Technique,LogReg,0.21902012825012207,1.078125,1.0
No Technique,GradientBoost,48.875853300094604,2.0,0.9666666666666667
No Technique,GradientBoost,49.85462522506714,2.00390625,0.9666666666666667
No Technique,GradientBoost,49.09519577026367,2.0,1.0
No Technique,GradientBoost,49.39320492744446,2.0078125,1.0
No Technique,GradientBoost,48.84408950805664,2.23046875,1.0
No Technique,GradientBoost,47.60294270515442,2.1171875,1.0
No Technique,GradientBoost,27.653729915618896,1.96484375,1.0
No Technique,GradientBoost,48.39579749107361,1.99609375,1.0
No Technique,GradientBoost,46.64413547515869,2.00390625,0.9666666666666667
No Technique,GradientBoost,48.7408082485199,2.1015625,1.0
No Technique,GradientBoost,48.546053647994995,2.0859375,1.0
No Technique,GradientBoost,48.82020688056946,2.0625,1.0
No Technique,GradientBoost,48.78522348403931,1.953125,1.0
No Technique,GradientBoost,48.2314293384552,2.23828125,0.9666666666666667
No Technique,GradientBoost,48.23650026321411,1.93359375,0.9666666666666667
No Technique,GradientBoost,36.617570638656616,2.00390625,1.0
No Technique,GradientBoost,48.61714243888855,1.97265625,1.0
No Technique,GradientBoost,49.17488622665405,1.984375,0.9666666666666667
No Technique,GradientBoost,47.988810300827026,2.04296875,1.0
No Technique,GradientBoost,47.92386174201965,2.0546875,1.0
No Technique,XGBoost,8.836820363998413,16.21484375,1.0
No Technique,XGBoost,9.530390977859497,16.1953125,0.9666666666666667
No Technique,XGBoost,11.58090090751648,14.3671875,0.9666666666666667
No Technique,XGBoost,9.044894933700562,16.33203125,1.0
No Technique,XGBoost,10.082016944885254,15.73828125,1.0
No Technique,XGBoost,9.218748569488525,16.36328125,0.9
No Technique,XGBoost,8.599371671676636,16.515625,1.0
No Technique,XGBoost,10.53731393814087,16.5,0.9333333333333333
No Technique,XGBoost,8.742640495300293,15.765625,1.0
No Technique,XGBoost,8.995929479598999,15.4765625,0.9666666666666667
No Technique,XGBoost,8.527183294296265,15.62890625,0.9
No Technique,XGBoost,9.194695472717285,16.015625,1.0
No Technique,XGBoost,7.958345413208008,15.23828125,1.0
No Technique,XGBoost,11.663727045059204,16.546875,1.0
No Technique,XGBoost,9.231312274932861,15.75390625,1.0
No Technique,XGBoost,8.891187191009521,16.15234375,0.9666666666666667
No Technique,XGBoost,8.849376440048218,15.234375,1.0
No Technique,XGBoost,10.135197639465332,15.859375,1.0
No Technique,XGBoost,9.151458263397217,15.54296875,0.9333333333333333
No Technique,XGBoost,9.10304045677185,15.2890625,1.0
